Workbook

Sheet C.R Sem. 2025
A1: Période | B1: Catégorie | C1: Amanda | D1: Emile | E1: Brandon | F1: Immersion | G1: Elsa | H1: Laureen-Lee | I1: Brice | J1: Lamia | K1: Global
A2: S2 - Janvier | B2: Oui | C2: 2 | I2: 0 | J2: 1 | K2: =SUM(C2,I2,J2) -> 3 | L2: Nouveaux clients
B3: Non | C3: 33 | I3: 14 | J3: 20 | K3: =SUM(C3,I3,J3) -> 67
B4: Ne répond pas | C4: 26 | I4: 22 | J4: 35 | K4: =SUM(C4,I4,J4) -> 83
B5: À réfléchir | C5: 28 | I5: 3 | J5: 5 | K5: =SUM(C5,I5,J5) -> 36
B6: Relance | C6: 17 | I6: 0 | J6: 0 | K6: =SUM(C6,I6,J6) -> 17
B7: Total d'appel | C7: 106 | I7: 39 | J7: 61 | K7: =SUM(C7,I7,J7) -> 206
B8: Total trier | C8: 427 | I8: 174 | J8: 256 | K8: =SUM(C8,I8,J8) -> 857
B9: Nbre d'ent. fermé | C9: 173 | I9: 88 | J9: 134 | K9: =SUM(C9,I9,J9) -> 395
B10: Nbre d'ent. ouvert | C10: 254 | I10: 86 | J10: 132 | K10: =SUM(C10,I10,J10) -> 472
A11: S3 | B11: Oui | C11: 3 | I11: 2 | J11: 2 | K11: =SUM(C11,I11,J11) -> 7 | L11: Nouveaux clients
B12: Non | C12: 40 | I12: 14 | J12: 31 | K12: =SUM(C12,I12,J12) -> 85
B13: Ne répond pas | C13: 32 | I13: 16 | J13: 65 | K13: =SUM(C13,I13,J13) -> 113
B14: À réfléchir | C14: 27 | I14: 2 | J14: 5 | K14: =SUM(C14,I14,J14) -> 34
B15: Relance | C15: 16 | I15: 45 | J15: 0 | K15: =SUM(C15,I15,J15) -> 61
B16: Total d'appel | C16: 118 | I16: 107 | J16: 104 | K16: =SUM(C16,I16,J16) -> 329
B17: Total trier | C17: 154 | I17: 160 | J17: 145 | K17: =SUM(C17,I17,J17) -> 459
B18: Nbre d'ent. fermé | C18: 46 | I18: 108 | J18: 83 | K18: =SUM(C18,I18,J18) -> 237
B19: Nbre d'ent. ouvert | C19: 108 | I19: 52 | J19: 62 | K19: =SUM(C19,I19,J19) -> 222
A20: S4 | B20: Oui | C20: 0 | I20: 2 | J20: 0 | K20: =SUM(C20,I20,J20) -> 2 | L20: Nouveaux clients
B21: Non | C21: 36 | I21: 15 | J21: 30 | K21: =SUM(C21,I21,J21) -> 81
B22: Ne répond pas | C22: 28 | I22: 35 | J22: 40 | K22: =SUM(C22,I22,J22) -> 103
B23: À réfléchir | C23: 24 | I23: 3 | J23: 16 | K23: =SUM(C23,I23,J23) -> 43
B24: Relance | C24: 3 | I24: 12 | J24: 0 | K24: =SUM(C24,I24,J24) -> 15
B25: Total d'appel | C25: 91 | I25: 85 | J25: 86 | K25: =SUM(C25,I25,J25) -> 262
B26: Total trier | C26: 180 | I26: 150 | J26: 164 | K26: =SUM(C26,I26,J26) -> 494
B27: Nbre d'ent. fermé | C27: 75 | I27: 77 | J27: 74 | K27: =SUM(C27,I27,J27) -> 226
B28: Nbre d'ent. ouvert | C28: 105 | I28: 73 | J28: 90 | K28: =SUM(C28,I28,J28) -> 268
A29: S5 | B29: Oui | C29: 3 | I29: 2 | J29: 0 | K29: =SUM(C29,I29,J29) -> 5 | L29: Nouveaux clients
B30: Non | C30: 36 | J30: 37 | K30: =SUM(C30,I30,J30) -> 73
B31: Ne répond pas | C31: 31 | J31: 39 | K31: =SUM(C31,I31,J31) -> 70
B32: À réfléchir | C32: 21 | I32: 10 | J32: 5 | K32: =SUM(C32,I32,J32) -> 36
B33: Relance | C33: 0 | J33: 0 | K33: =SUM(C33,I33,J33) -> 0
B34: Total d'appel | C34: 91 | I34: 92 | J34: 81 | K34: =SUM(C34,I34,J34) -> 264
B35: Total trier | C35: 171 | I35: 162 | J35: 219 | K35: =SUM(C35,I35,J35) -> 552
B36: Nbre d'ent. fermé | C36: 72 | J36: 105 | K36: =SUM(C36,I36,J36) -> 177
B37: Nbre d'ent. ouvert | C37: 99 | I37: 52 | J37: 114 | K37: =SUM(C37,I37,J37) -> 265
A38: S6 - Février | B38: Oui | C38: 4 | I38: 0 | J38: 3 | K38: =SUM(C38,I38,J38) -> 7 | L38: Nouveaux Contrats
B39: Non | C39: 38 | J39: 18 | K39: =SUM(C39,I39,J39) -> 56
B40: Ne répond pas | C40: 27 | J40: 38 | K40: =SUM(C40,I40,J40) -> 65
...

Sheet C.R Sem. 2026
A1: * | B1: Catégorie | C1: Amanda | D1: Emile | E1: Brandon | F1: Immersion
A2: S2 - Janvier | B2: Visite entreprises | D2: 2 | E2: 2
B3: Oui OF
B4: Oui | C4: 7 | D4: 4 | E4: 4 | G4: =SUM(C4:F4) -> 15
B5: Non | C5: 5 | D5: 18 | E5: 12
B6: Ne répond pas | C6: 3 | D6: 34 | E6: 19
B7: À réfléchir | C7: 4 | D7: 6 | E7: 8
B8: Relance | C8: 7 | D8: 8 | E8: 9
B9: Total d'appel | C9: =SUM(C4:C8) -> 26 | D9: 71 | E9: 53 | F9: =SUM(F4:F8) -> 0
B10: Total trier | F10: =SUM(F11:F12) -> 0
B11: Nbre d'ent. fermé | E11: 8
B12: Nbre d'ent. ouvert | C12: =C9 -> 26 | D12: =D9 -> 71 | E12: =E9-E11 -> 45
A13: S3 | B13: Visite entreprises | D13: 5 | E13: 5
B14: Oui OF | E14: 1 | G14: =SUM(C14:F14) -> 1
B15: Oui | C15: 6 | D15: 5 | E15: 4 | G15: =SUM(C15:F15) -> 15
B16: Non | C16: 19 | D16: 20 | E16: 15
B17: Ne répond pas | C17: 14 | D17: 24 | E17: 23
B18: À réfléchir | C18: 6 | D18: 8 | E18: 14
B19: Relance | C19: 12 | D19: 6 | E19: 6
B20: Total d'appel | C20: =SUM(C15:C19) -> 57 | D20: 72 | E20: 63 | F20: =SUM(F15:F19) -> 0
B21: Total trier | F21: =SUM(F22:F23) -> 0
B22: Nbre d'ent. fermé | E22: 2
B23: Nbre d'ent. ouvert | C23: =C20 -> 57 | D23: =D20 -> 72 | E23: =E20-E22 -> 61
A24: S4 | B24: Visite entreprises | E24: 5
B25: Oui OF | C25: 3 | E25: 2 | G25: =SUM(C25:F25) -> 5
B26: Oui | C26: 6 | D26: 4 | E26: 7 | G26: =SUM(C26:F26) -> 17
B27: Non | C27: 14 | D27: 17 | E27: 10
B28: Ne répond pas | C28: 11 | D28: 23 | E28: 32
B29: À réfléchir | C29: 9 | D29: 13 | E29: 5
B30: Relance | C30: 10 | D30: 15 | E30: 8
B31: Total d'appel | C31: =SUM(C26:C30) -> 50 | D31: =SUM(D26:D30) -> 72 | E31: =SUM(E26:E30) -> 62 | F31: =SUM(F26:F30) -> 0
B32: Total trier | F32: =SUM(F33:F34) -> 0
B33: Nbre d'ent. fermé | C33: 2
B34: Nbre d'ent. ouvert | C34: =C31-C33 -> 48 | D34: =D31 -> 72 | E34: =E31 -> 62
A35: S5 | B35: Visite entreprises | D35: 4 | E35: 4
B36: Oui OF | G36: =SUM(C36:F36) -> 0
B37: Oui | C37: 9 | D37: 10 | E37: 6 | G37: =SUM(C37:F37) -> 25
B38: Non | C38: 15 | D38: 16 | E38: 12
B39: Ne répond pas | C39: 10 | D39: 6 | E39: 31
B40: À réfléchir | C40: 5 | D40: 9 | E40: 4
...

Sheet C.R Mois 2026
A1: Période | B1: Catégorie | C1: Amanda | D1: Emile | E1: Brandon | F1: Immersion | G1: Total | H1: Comparatif N-1 | I1: Écart N-1 | J1: Évolution% N-1 | L1: Non employé
A2: Janvier | B2: Oui | C2: =SUM('C.R Sem. 2026'!C4,'C.R Sem. 2026'!C15,'C.R Sem. 2026'!C26,'C.R Sem. 2026'!C37) -> 28 | D2: =SUM('C.R Sem. 2026'!D4,'C.R Sem. 2026'!D15,'C.R Sem. 2026'!D26,'C.R Sem. 2026'!D37) -> 23 | E2: =SUM('C.R Sem. 2026'!E4,'C.R Sem. 2026'!E15,'C.R Sem. 2026'!E26,'C.R Sem. 2026'!E37) -> 21 | F2: =SUM('C.R Sem. 2026'!F4,'C.R Sem. 2026'!F15,'C.R Sem. 2026'!F26,'C.R Sem. 2026'!F37) -> 0 | G2: =SUM(C2:F2) -> 72 | H2: =IF(G2>'C.R Mois 2025'!K2,"↑",IF(G2<'C.R Mois 2025'!K2,"↓","→")) -> ↑ | I2: =G2-'C.R Mois 2025'!K2 -> 55 | J2: =(G2-'C.R Mois 2025'!K2)/'C.R Mois 2025'!K2 -> 3.2352941
B3: Oui OF | C3: =SUM('C.R Sem. 2026'!C3,'C.R Sem. 2026'!C14,'C.R Sem. 2026'!C25,'C.R Sem. 2026'!C36) -> 3 | D3: =SUM('C.R Sem. 2026'!D3,'C.R Sem. 2026'!D14,'C.R Sem. 2026'!D25,'C.R Sem. 2026'!D36) -> 0 | E3: =SUM('C.R Sem. 2026'!E3,'C.R Sem. 2026'!E14,'C.R Sem. 2026'!E25,'C.R Sem. 2026'!E36) -> 3 | F3: =SUM('C.R Sem. 2026'!F3,'C.R Sem. 2026'!F14,'C.R Sem. 2026'!F25,'C.R Sem. 2026'!F36) -> 0 | G3: =SUM(C3:F3) -> 6 | L3: ANNÉE | M3: JANVIER | N3: FÉVRIER | O3: MARS | P3: AVRIL | Q3: MAI | R3: JUIN | S3: JUILLET | T3: AOUT | U3: SEPTEMBRE | V3: OCTOBRE | W3: NOVEMBRE | X3: DÉCEMBRE | Y3: TOTAL
B4: À réfléchir | C4: =SUM('C.R Sem. 2026'!C7,'C.R Sem. 2026'!C18,'C.R Sem. 2026'!C29,'C.R Sem. 2026'!C40) -> 24 | D4: =SUM('C.R Sem. 2026'!D7,'C.R Sem. 2026'!D18,'C.R Sem. 2026'!D29,'C.R Sem. 2026'!D40) -> 36 | E4: =SUM('C.R Sem. 2026'!E7,'C.R Sem. 2026'!E18,'C.R Sem. 2026'!E29,'C.R Sem. 2026'!E40) -> 31 | F4: =SUM('C.R Sem. 2026'!F7,'C.R Sem. 2026'!F18,'C.R Sem. 2026'!F29,'C.R Sem. 2026'!F40) -> 0 | L4: GLOBAL OUI 2025 | M4: ='C.R Mois 2025'!K2 -> 17 | N4: ='C.R Mois 2025'!K7 -> 38 | O4: ='C.R Mois 2025'!K12 -> 75 | P4: ='C.R Mois 2025'!K17 -> 35 | Q4: ='C.R Mois 2025'!K22 -> 53 | R4: ='C.R Mois 2025'!K27 -> 40 | S4: ='C.R Mois 2025'!K32 -> 61 | T4: ='C.R Mois 2025'!K37 -> 83 | U4: ='C.R Mois 2025'!K42 -> 91 | V4: ='C.R Mois 2025'!K47 -> 85 | W4: ='C.R Mois 2025'!K52 -> 34 | X4: ='C.R Mois 2025'!K57 -> 17 | Y4: ='C.R Mois 2025'!K62 -> 629
B5: Total d'appel | C5: =SUM('C.R Sem. 2026'!C9,'C.R Sem. 2026'!C20,'C.R Sem. 2026'!C31,'C.R Sem. 2026'!C42) -> 183 | D5: =SUM('C.R Sem. 2026'!D9,'C.R Sem. 2026'!D20,'C.R Sem. 2026'!D31,'C.R Sem. 2026'!D42) -> 263 | E5: =SUM('C.R Sem. 2026'!E9,'C.R Sem. 2026'!E20,'C.R Sem. 2026'!E31,'C.R Sem. 2026'!E42) -> 239 | F5: =SUM('C.R Sem. 2026'!F9,'C.R Sem. 2026'!F20,'C.R Sem. 2026'!F31,'C.R Sem. 2026'!F42) -> 0 | L5: GLOBAL OUI 2026 | M5: =G2 -> 72 | N5: =G8 -> 48 | O5: =G14 -> 87 | P5: =G20 -> 59 | Q5: =G26 -> 58 | R5: =G32 -> 25 | S5: =G38 -> 0 | T5: =G44 -> 0 | U5: =G50 -> 0 | V5: =G56 -> 0 | W5: =G62 -> 0 | X5: =G68 -> 0 | Y5: =G74 -> 349
B6: Total trier | C6: =SUM('C.R Sem. 2026'!C43,'C.R Sem. 2026'!C32,'C.R Sem. 2026'!C21,'C.R Sem. 2026'!C10) -> 0 | D6: =SUM('C.R Sem. 2026'!D43,'C.R Sem. 2026'!D32,'C.R Sem. 2026'!D21,'C.R Sem. 2026'!D10) -> 0 | E6: =SUM('C.R Sem. 2026'!E43,'C.R Sem. 2026'!E32,'C.R Sem. 2026'!E21,'C.R Sem. 2026'!E10) -> 0 | F6: =SUM('C.R Sem. 2026'!F43,'C.R Sem. 2026'!F32,'C.R Sem. 2026'!F21,'C.R Sem. 2026'!F10) -> 0
B7: Nbre d'ent. ouvert | C7: =SUM('C.R Sem. 2026'!C12,'C.R Sem. 2026'!C23,'C.R Sem. 2026'!C34,'C.R Sem. 2026'!C45) -> 181 | D7: =SUM('C.R Sem. 2026'!D12,'C.R Sem. 2026'!D23,'C.R Sem. 2026'!D34,'C.R Sem. 2026'!D45) -> 263 | E7: =SUM('C.R Sem. 2026'!E12,'C.R Sem. 2026'!E23,'C.R Sem. 2026'!E34,'C.R Sem. 2026'!E45) -> 228 | F7: =SUM('C.R Sem. 2026'!F12,'C.R Sem. 2026'!F23,'C.R Sem. 2026'!F34,'C.R Sem. 2026'!F45) -> 0
A8: Février | B8: Oui | C8: =SUM('C.R Sem. 2026'!C48,'C.R Sem. 2026'!C59,'C.R Sem. 2026'!C70,'C.R Sem. 2026'!C81) -> 13 | D8: =SUM('C.R Sem. 2026'!D48,'C.R Sem. 2026'!D59,'C.R Sem. 2026'!D70,'C.R Sem. 2026'!D81) -> 15 | E8: =SUM('C.R Sem. 2026'!E48,'C.R Sem. 2026'!E59,'C.R Sem. 2026'!E70,'C.R Sem. 2026'!E81) -> 20 | F8: =SUM('C.R Sem. 2026'!F48,'C.R Sem. 2026'!F59,'C.R Sem. 2026'!F70,'C.R Sem. 2026'!F81) -> 0 | G8: =SUM(C8:F8) -> 48 | H8: =IF(G8>'C.R Mois 2025'!K7,"↑",IF(G8<'C.R Mois 2025'!K7,"↓","→")) -> ↑ | I8: =G8-'C.R Mois 2025'!K7 -> 10 | J8: =(G8-'C.R Mois 2025'!K7)/'C.R Mois 2025'!K7 -> 0.26315789
B9: Oui OF | C9: =SUM('C.R Sem. 2026'!C47,'C.R Sem. 2026'!C58,'C.R Sem. 2026'!C69,'C.R Sem. 2026'!C80) -> 3 | D9: =SUM('C.R Sem. 2026'!D47,'C.R Sem. 2026'!D58,'C.R Sem. 2026'!D69,'C.R Sem. 2026'!D80) -> 0 | E9: =SUM('C.R Sem. 2026'!E47,'C.R Sem. 2026'!E58,'C.R Sem. 2026'!E69,'C.R Sem. 2026'!E80) -> 2 | F9: =SUM('C.R Sem. 2026'!F47,'C.R Sem. 2026'!F58,'C.R Sem. 2026'!F69,'C.R Sem. 2026'!F80) -> 0 | G9: =SUM(C9:F9) -> 5
B10: À réfléchir | C10: =SUM('C.R Sem. 2026'!C84,'C.R Sem. 2026'!C73,'C.R Sem. 2026'!C62,'C.R Sem. 2026'!C51) -> 26 | D10: =SUM('C.R Sem. 2026'!D84,'C.R Sem. 2026'!D73,'C.R Sem. 2026'!D62,'C.R Sem. 2026'!D51) -> 34 | E10: =SUM('C.R Sem. 2026'!E84,'C.R Sem. 2026'!E73,'C.R Sem. 2026'!E62,'C.R Sem. 2026'!E51) -> 33 | F10: =SUM('C.R Sem. 2026'!F84,'C.R Sem. 2026'!F73,'C.R Sem. 2026'!F62,'C.R Sem. 2026'!F51) -> 0
B11: Total d'appel | C11: =SUM('C.R Sem. 2026'!C86,'C.R Sem. 2026'!C75,'C.R Sem. 2026'!C64,'C.R Sem. 2026'!C53) -> 153 | D11: =SUM('C.R Sem. 2026'!D86,'C.R Sem. 2026'!D75,'C.R Sem. 2026'!D64,'C.R Sem. 2026'!D53) -> 256 | E11: =SUM('C.R Sem. 2026'!E86,'C.R Sem. 2026'!E75,'C.R Sem. 2026'!E64,'C.R Sem. 2026'!E53) -> 254 | F11: =SUM('C.R Sem. 2026'!F86,'C.R Sem. 2026'!F75,'C.R Sem. 2026'!F64,'C.R Sem. 2026'!F53) -> 0
B12: Total trier | C12: =SUM('C.R Sem. 2026'!C54,'C.R Sem. 2026'!C65,'C.R Sem. 2026'!C76,'C.R Sem. 2026'!C87) -> 0 | D12: =SUM('C.R Sem. 2026'!D54,'C.R Sem. 2026'!D65,'C.R Sem. 2026'!D76,'C.R Sem. 2026'!D87) -> 0 | E12: =SUM('C.R Sem. 2026'!E54,'C.R Sem. 2026'!E65,'C.R Sem. 2026'!E76,'C.R Sem. 2026'!E87) -> 0 | F12: =SUM('C.R Sem. 2026'!F54,'C.R Sem. 2026'!F65,'C.R Sem. 2026'!F76,'C.R Sem. 2026'!F87) -> 0
B13: Nbre d'ent. ouvert | C13: =SUM('C.R Sem. 2026'!C56,'C.R Sem. 2026'!C67,'C.R Sem. 2026'!C78,'C.R Sem. 2026'!C89) -> 142 | D13: =SUM('C.R Sem. 2026'!D56,'C.R Sem. 2026'!D67,'C.R Sem. 2026'!D78,'C.R Sem. 2026'!D89) -> 256 | E13: =SUM('C.R Sem. 2026'!E56,'C.R Sem. 2026'!E67,'C.R Sem. 2026'!E78,'C.R Sem. 2026'!E89) -> 248 | F13: =SUM('C.R Sem. 2026'!F56,'C.R Sem. 2026'!F67,'C.R Sem. 2026'!F78,'C.R Sem. 2026'!F89) -> 0
A14: Mars | B14: Oui | C14: =SUM('C.R Sem. 2026'!C92,'C.R Sem. 2026'!C103,'C.R Sem. 2026'!C114,'C.R Sem. 2026'!C125,'C.R Sem. 2026'!C136) -> 37 | D14: =SUM('C.R Sem. 2026'!D92,'C.R Sem. 2026'!D103,'C.R Sem. 2026'!D114,'C.R Sem. 2026'!D125,'C.R Sem. 2026'!D136) -> 25 | E14: =SUM('C.R Sem. 2026'!E92,'C.R Sem. 2026'!E103,'C.R Sem. 2026'!E114,'C.R Sem. 2026'!E125,'C.R Sem. 2026'!E136) -> 25 | F14: =SUM('C.R Sem. 2026'!F92,'C.R Sem. 2026'!F103,'C.R Sem. 2026'!F114,'C.R Sem. 2026'!F125,'C.R Sem. 2026'!F136) -> 0 | G14: =SUM(C14:F14) -> 87 | H14: =IF(G14>'C.R Mois 2025'!K12,"↑",IF(G14<'C.R Mois 2025'!K12,"↓","→")) -> ↑ | I14: =G14-'C.R Mois 2025'!K12 -> 12 | J14: =(G14-'C.R Mois 2025'!K12)/'C.R Mois 2025'!K12 -> 0.16
B15: Oui OF | C15: =SUM('C.R Sem. 2026'!C91,'C.R Sem. 2026'!C102,'C.R Sem. 2026'!C113,'C.R Sem. 2026'!C124) -> 1 | D15: =SUM('C.R Sem. 2026'!D91,'C.R Sem. 2026'!D102,'C.R Sem. 2026'!D113,'C.R Sem. 2026'!D124) -> 1 | E15: =SUM('C.R Sem. 2026'!E91,'C.R Sem. 2026'!E102,'C.R Sem. 2026'!E113,'C.R Sem. 2026'!E124) -> 3 | F15: =SUM('C.R Sem. 2026'!F91,'C.R Sem. 2026'!F102,'C.R Sem. 2026'!F113,'C.R Sem. 2026'!F124) -> 0 | G15: =SUM(C15:F15) -> 5
B16: À réfléchir | C16: =SUM('C.R Sem. 2026'!C139,'C.R Sem. 2026'!C128,'C.R Sem. 2026'!C117,'C.R Sem. 2026'!C106,'C.R Sem. 2026'!C95) -> 43 | D16: =SUM('C.R Sem. 2026'!D139,'C.R Sem. 2026'!D128,'C.R Sem. 2026'!D117,'C.R Sem. 2026'!D106,'C.R Sem. 2026'!D95) -> 38 | E16: =SUM('C.R Sem. 2026'!E139,'C.R Sem. 2026'!E128,'C.R Sem. 2026'!E117,'C.R Sem. 2026'!E106,'C.R Sem. 2026'!E95) -> 39 | F16: =SUM('C.R Sem. 2026'!F139,'C.R Sem. 2026'!F128,'C.R Sem. 2026'!F117,'C.R Sem. 2026'!F106,'C.R Sem. 2026'!F95) -> 0
B17: Total d'appel | C17: =SUM('C.R Sem. 2026'!C97,'C.R Sem. 2026'!C108,'C.R Sem. 2026'!C119,'C.R Sem. 2026'!C130,'C.R Sem. 2026'!C141) -> 248 | D17: =SUM('C.R Sem. 2026'!D97,'C.R Sem. 2026'!D108,'C.R Sem. 2026'!D119,'C.R Sem. 2026'!D130,'C.R Sem. 2026'!D141) -> 337 | E17: =SUM('C.R Sem. 2026'!E97,'C.R Sem. 2026'!E108,'C.R Sem. 2026'!E119,'C.R Sem. 2026'!E130,'C.R Sem. 2026'!E141) -> 266 | F17: =SUM('C.R Sem. 2026'!F97,'C.R Sem. 2026'!F108,'C.R Sem. 2026'!F119,'C.R Sem. 2026'!F130,'C.R Sem. 2026'!F141) -> 0
B18: Total trier | C18: =SUM('C.R Sem. 2026'!C142,'C.R Sem. 2026'!C131,'C.R Sem. 2026'!C120,'C.R Sem. 2026'!C109,'C.R Sem. 2026'!C98) -> 0 | D18: =SUM('C.R Sem. 2026'!D142,'C.R Sem. 2026'!D131,'C.R Sem. 2026'!D120,'C.R Sem. 2026'!D109,'C.R Sem. 2026'!D98) -> 0 | E18: =SUM('C.R Sem. 2026'!E142,'C.R Sem. 2026'!E131,'C.R Sem. 2026'!E120,'C.R Sem. 2026'!E109,'C.R Sem. 2026'!E98) -> 45 | F18: =SUM('C.R Sem. 2026'!F142,'C.R Sem. 2026'!F131,'C.R Sem. 2026'!F120,'C.R Sem. 2026'!F109,'C.R Sem. 2026'!F98) -> 0
B19: Nbre d'ent. ouvert | C19: =SUM('C.R Sem. 2026'!C100,'C.R Sem. 2026'!C111,'C.R Sem. 2026'!C122,'C.R Sem. 2026'!C133,'C.R Sem. 2026'!C144) -> 243 | D19: =SUM('C.R Sem. 2026'!D100,'C.R Sem. 2026'!D111,'C.R Sem. 2026'!D122,'C.R Sem. 2026'!D133,'C.R Sem. 2026'!D144) -> 337 | E19: =SUM('C.R Sem. 2026'!E100,'C.R Sem. 2026'!E111,'C.R Sem. 2026'!E122,'C.R Sem. 2026'!E133,'C.R Sem. 2026'!E144) -> 255 | F19: =SUM('C.R Sem. 2026'!F100,'C.R Sem. 2026'!F111,'C.R Sem. 2026'!F122,'C.R Sem. 2026'!F133,'C.R Sem. 2026'!F144) -> 0
A20: Avril | B20: Oui | C20: =SUM('C.R Sem. 2026'!C147,'C.R Sem. 2026'!C158,'C.R Sem. 2026'!C169,'C.R Sem. 2026'!C180) -> 22 | D20: =SUM('C.R Sem. 2026'!D147,'C.R Sem. 2026'!D158,'C.R Sem. 2026'!D169,'C.R Sem. 2026'!D180) -> 19 | E20: =SUM('C.R Sem. 2026'!E147,'C.R Sem. 2026'!E158,'C.R Sem. 2026'!E169,'C.R Sem. 2026'!E180) -> 18 | F20: =SUM('C.R Sem. 2026'!F147,'C.R Sem. 2026'!F158,'C.R Sem. 2026'!F169,'C.R Sem. 2026'!F180) -> 0 | G20: =SUM(C20:F20) -> 59 | H20: =IF(G20>'C.R Mois 2025'!K17,"↑",IF(G20<'C.R Mois 2025'!K17,"↓","→")) -> ↑ | I20: =G20-'C.R Mois 2025'!K17 -> 24 | J20: =(G20-'C.R Mois 2025'!K17)/'C.R Mois 2025'!K17 -> 0.68571429
B21: Oui OF | C21: =SUM('C.R Sem. 2026'!C179,'C.R Sem. 2026'!C168,'C.R Sem. 2026'!C157,'C.R Sem. 2026'!C146) -> 0 | D21: =SUM('C.R Sem. 2026'!D179,'C.R Sem. 2026'!D168,'C.R Sem. 2026'!D157,'C.R Sem. 2026'!D146) -> 0 | E21: =SUM('C.R Sem. 2026'!E179,'C.R Sem. 2026'!E168,'C.R Sem. 2026'!E157,'C.R Sem. 2026'!E146) -> 1 | F21: =SUM('C.R Sem. 2026'!F179,'C.R Sem. 2026'!F168,'C.R Sem. 2026'!F157,'C.R Sem. 2026'!F146) -> 0 | G21: =SUM(C21:F21) -> 1
B22: À réfléchir | C22: =SUM('C.R Sem. 2026'!C150,'C.R Sem. 2026'!C161,'C.R Sem. 2026'!C172,'C.R Sem. 2026'!C183) -> 29 | D22: =SUM('C.R Sem. 2026'!D150,'C.R Sem. 2026'!D161,'C.R Sem. 2026'!D172,'C.R Sem. 2026'!D183) -> 44 | E22: =SUM('C.R Sem. 2026'!E150,'C.R Sem. 2026'!E161,'C.R Sem. 2026'!E172,'C.R Sem. 2026'!E183) -> 47 | F22: =SUM('C.R Sem. 2026'!F150,'C.R Sem. 2026'!F161,'C.R Sem. 2026'!F172,'C.R Sem. 2026'!F183) -> 0
B23: Total d'appel | C23: =SUM('C.R Sem. 2026'!C185,'C.R Sem. 2026'!C174,'C.R Sem. 2026'!C163,'C.R Sem. 2026'!C152) -> 203 | D23: =SUM('C.R Sem. 2026'!D185,'C.R Sem. 2026'!D174,'C.R Sem. 2026'!D163,'C.R Sem. 2026'!D152) -> 216 | E23: =SUM('C.R Sem. 2026'!E185,'C.R Sem. 2026'!E174,'C.R Sem. 2026'!E163,'C.R Sem. 2026'!E152) -> 216 | F23: =SUM('C.R Sem. 2026'!F185,'C.R Sem. 2026'!F174,'C.R Sem. 2026'!F163,'C.R Sem. 2026'!F152) -> 0
B24: Total trier | C24: =SUM('C.R Sem. 2026'!C153,'C.R Sem. 2026'!C164,'C.R Sem. 2026'!C175,'C.R Sem. 2026'!C186) -> 0 | D24: =SUM('C.R Sem. 2026'!D153,'C.R Sem. 2026'!D164,'C.R Sem. 2026'!D175,'C.R Sem. 2026'!D186) -> 0 | E24: =SUM('C.R Sem. 2026'!E153,'C.R Sem. 2026'!E164,'C.R Sem. 2026'!E175,'C.R Sem. 2026'!E186) -> 0 | F24: =SUM('C.R Sem. 2026'!F153,'C.R Sem. 2026'!F164,'C.R Sem. 2026'!F175,'C.R Sem. 2026'!F186) -> 0
B25: Nbre d'ent. ouvert | C25: =SUM('C.R Sem. 2026'!C155,'C.R Sem. 2026'!C166,'C.R Sem. 2026'!C177,'C.R Sem. 2026'!C188) -> 201 | D25: =SUM('C.R Sem. 2026'!D155,'C.R Sem. 2026'!D166,'C.R Sem. 2026'!D177,'C.R Sem. 2026'!D188) -> 216 | E25: =SUM('C.R Sem. 2026'!E155,'C.R Sem. 2026'!E166,'C.R Sem. 2026'!E177,'C.R Sem. 2026'!E188) -> 215 | F25: =SUM('C.R Sem. 2026'!F155,'C.R Sem. 2026'!F166,'C.R Sem. 2026'!F177,'C.R Sem. 2026'!F188) -> 0
A26: Mai | B26: Oui | C26: =SUM('C.R Sem. 2026'!C213,'C.R Sem. 2026'!C202,'C.R Sem. 2026'!C191,'C.R Sem. 2026'!C224) -> 13 | D26: =SUM('C.R Sem. 2026'!D213,'C.R Sem. 2026'!D202,'C.R Sem. 2026'!D191,'C.R Sem. 2026'!D224) -> 24 | E26: =SUM('C.R Sem. 2026'!E213,'C.R Sem. 2026'!E202,'C.R Sem. 2026'!E191,'C.R Sem. 2026'!E224) -> 21 | F26: =SUM('C.R Sem. 2026'!F213,'C.R Sem. 2026'!F202,'C.R Sem. 2026'!F191,'C.R Sem. 2026'!F224) -> 0 | G26: =SUM(C26:F26) -> 58 | H26: =IF(G26>'C.R Mois 2025'!K22,"↑",IF(G26<'C.R Mois 2025'!K22,"↓","→")) -> ↑ | I26: =G26-'C.R Mois 2025'!K22 -> 5 | J26: =(G26-'C.R Mois 2025'!K22)/'C.R Mois 2025'!K22 -> 0.094339623
B27: Oui OF | C27: =SUM('C.R Sem. 2026'!C212,'C.R Sem. 2026'!C201,'C.R Sem. 2026'!C190,'C.R Sem. 2026'!C223) -> 1 | D27: =SUM('C.R Sem. 2026'!D212,'C.R Sem. 2026'!D201,'C.R Sem. 2026'!D190,'C.R Sem. 2026'!D223) -> 0 | E27: =SUM('C.R Sem. 2026'!E212,'C.R Sem. 2026'!E201,'C.R Sem. 2026'!E190,'C.R Sem. 2026'!E223) -> 1 | F27: =SUM('C.R Sem. 2026'!F212,'C.R Sem. 2026'!F201,'C.R Sem. 2026'!F190,'C.R Sem. 2026'!F223) -> 0 | G27: =SUM(C27:F27) -> 2
B28: À réfléchir | C28: =SUM('C.R Sem. 2026'!C194,'C.R Sem. 2026'!C205,'C.R Sem. 2026'!C216,'C.R Sem. 2026'!C227) -> 14 | D28: =SUM('C.R Sem. 2026'!D227,'C.R Sem. 2026'!D216,'C.R Sem. 2026'!D205,'C.R Sem. 2026'!D194) -> 39 | E28: =SUM('C.R Sem. 2026'!E194,'C.R Sem. 2026'!E205,'C.R Sem. 2026'!E216,'C.R Sem. 2026'!E227) -> 33 | F28: =SUM('C.R Sem. 2026'!F194,'C.R Sem. 2026'!F205,'C.R Sem. 2026'!F216,'C.R Sem. 2026'!F227) -> 0
B29: Total d'appel | C29: =SUM('C.R Sem. 2026'!C229,'C.R Sem. 2026'!C218,'C.R Sem. 2026'!C207,'C.R Sem. 2026'!C196) -> 106 | D29: =SUM('C.R Sem. 2026'!D229,'C.R Sem. 2026'!D218,'C.R Sem. 2026'!D207,'C.R Sem. 2026'!D196) -> 263 | E29: =SUM('C.R Sem. 2026'!E229,'C.R Sem. 2026'!E218,'C.R Sem. 2026'!E207,'C.R Sem. 2026'!E196) -> 204 | F29: =SUM('C.R Sem. 2026'!F229,'C.R Sem. 2026'!F218,'C.R Sem. 2026'!F207,'C.R Sem. 2026'!F196) -> 0
B30: Total trier | C30: =SUM('C.R Sem. 2026'!C208,'C.R Sem. 2026'!C197,'C.R Sem. 2026'!C219,'C.R Sem. 2026'!C230) -> 0 | D30: =SUM('C.R Sem. 2026'!D208,'C.R Sem. 2026'!D197,'C.R Sem. 2026'!D219,'C.R Sem. 2026'!D230) -> 0 | E30: =SUM('C.R Sem. 2026'!E208,'C.R Sem. 2026'!E197,'C.R Sem. 2026'!E219,'C.R Sem. 2026'!E230) -> 0 | F30: =SUM('C.R Sem. 2026'!F208,'C.R Sem. 2026'!F197,'C.R Sem. 2026'!F219,'C.R Sem. 2026'!F230) -> 0
B31: Nbre d'ent. ouvert | C31: =SUM('C.R Sem. 2026'!C232,'C.R Sem. 2026'!C221,'C.R Sem. 2026'!C210,'C.R Sem. 2026'!C199) -> 106 | D31: =SUM('C.R Sem. 2026'!D232,'C.R Sem. 2026'!D221,'C.R Sem. 2026'!D210,'C.R Sem. 2026'!D199) -> 263 | E31: =SUM('C.R Sem. 2026'!E232,'C.R Sem. 2026'!E221,'C.R Sem. 2026'!E210,'C.R Sem. 2026'!E199) -> 197 | F31: =SUM('C.R Sem. 2026'!F232,'C.R Sem. 2026'!F221,'C.R Sem. 2026'!F210,'C.R Sem. 2026'!F199) -> 0
A32: Juin | B32: Oui | C32: =SUM('C.R Sem. 2026'!C235,'C.R Sem. 2026'!C246,'C.R Sem. 2026'!C257,'C.R Sem. 2026'!C268,'C.R Sem. 2026'!C279) -> 6 | D32: =SUM('C.R Sem. 2026'!D235,'C.R Sem. 2026'!D246,'C.R Sem. 2026'!D257,'C.R Sem. 2026'!D268,'C.R Sem. 2026'!D279) -> 14 | E32: =SUM('C.R Sem. 2026'!E235,'C.R Sem. 2026'!E246,'C.R Sem. 2026'!E257,'C.R Sem. 2026'!E268,'C.R Sem. 2026'!E279) -> 5 | F32: =SUM('C.R Sem. 2026'!F235,'C.R Sem. 2026'!F246,'C.R Sem. 2026'!F257,'C.R Sem. 2026'!F268,'C.R Sem. 2026'!F279) -> 0 | G32: =SUM(C32:F32) -> 25 | H32: =IF(G32>'C.R Mois 2025'!K27,"↑",IF(G32<'C.R Mois 2025'!K27,"↓","→")) -> ↓ | I32: =G32-'C.R Mois 2025'!K27 -> -15 | J32: =(G32-'C.R Mois 2025'!K27)/'C.R Mois 2025'!K27 -> -0.375
B33: Oui OF | C33: =SUM('C.R Sem. 2026'!C278,'C.R Sem. 2026'!C267,'C.R Sem. 2026'!C256,'C.R Sem. 2026'!C245,'C.R Sem. 2026'!C234) -> 0 | D33: =SUM('C.R Sem. 2026'!D278,'C.R Sem. 2026'!D267,'C.R Sem. 2026'!D256,'C.R Sem. 2026'!D245,'C.R Sem. 2026'!D234) -> 0 | E33: =SUM('C.R Sem. 2026'!E278,'C.R Sem. 2026'!E267,'C.R Sem. 2026'!E256,'C.R Sem. 2026'!E245,'C.R Sem. 2026'!E234) -> 0 | F33: =SUM('C.R Sem. 2026'!F278,'C.R Sem. 2026'!F267,'C.R Sem. 2026'!F256,'C.R Sem. 2026'!F245,'C.R Sem. 2026'!F234) -> 0 | G33: =SUM(C33:F33) -> 0
B34: À réfléchir | C34: =SUM('C.R Sem. 2026'!C238,'C.R Sem. 2026'!C249,'C.R Sem. 2026'!C260,'C.R Sem. 2026'!C271,'C.R Sem. 2026'!C282) -> 6 | D34: =SUM('C.R Sem. 2026'!D238,'C.R Sem. 2026'!D249,'C.R Sem. 2026'!D260,'C.R Sem. 2026'!D271,'C.R Sem. 2026'!D282) -> 22 | E34: =SUM('C.R Sem. 2026'!E238,'C.R Sem. 2026'!E249,'C.R Sem. 2026'!E260,'C.R Sem. 2026'!E271,'C.R Sem. 2026'!E282) -> 12 | F34: =SUM('C.R Sem. 2026'!F238,'C.R Sem. 2026'!F249,'C.R Sem. 2026'!F260,'C.R Sem. 2026'!F271,'C.R Sem. 2026'!F282) -> 0
B35: Total d'appel | C35: =SUM('C.R Sem. 2026'!C284,'C.R Sem. 2026'!C273,'C.R Sem. 2026'!C262,'C.R Sem. 2026'!C251,'C.R Sem. 2026'!C240) -> 34 | D35: =SUM('C.R Sem. 2026'!D284,'C.R Sem. 2026'!D273,'C.R Sem. 2026'!D262,'C.R Sem. 2026'!D251,'C.R Sem. 2026'!D240) -> 112 | E35: =SUM('C.R Sem. 2026'!E284,'C.R Sem. 2026'!E273,'C.R Sem. 2026'!E262,'C.R Sem. 2026'!E251,'C.R Sem. 2026'!E240) -> 56 | F35: =SUM('C.R Sem. 2026'!F284,'C.R Sem. 2026'!F273,'C.R Sem. 2026'!F262,'C.R Sem. 2026'!F251,'C.R Sem. 2026'!F240) -> 0
B36: Total trier | C36: =SUM('C.R Sem. 2026'!C241,'C.R Sem. 2026'!C252,'C.R Sem. 2026'!C263,'C.R Sem. 2026'!C274,'C.R Sem. 2026'!C285) -> 0 | D36: =SUM('C.R Sem. 2026'!D241,'C.R Sem. 2026'!D252,'C.R Sem. 2026'!D263,'C.R Sem. 2026'!D274,'C.R Sem. 2026'!D285) -> 0 | E36: =SUM('C.R Sem. 2026'!E241,'C.R Sem. 2026'!E252,'C.R Sem. 2026'!E263,'C.R Sem. 2026'!E274,'C.R Sem. 2026'!E285) -> 0 | F36: =SUM('C.R Sem. 2026'!F241,'C.R Sem. 2026'!F252,'C.R Sem. 2026'!F263,'C.R Sem. 2026'!F274,'C.R Sem. 2026'!F285) -> 0
B37: Nbre d'ent. ouvert | C37: =SUM('C.R Sem. 2026'!C287,'C.R Sem. 2026'!C276,'C.R Sem. 2026'!C265,'C.R Sem. 2026'!C254,'C.R Sem. 2026'!C243) -> 32 | D37: =SUM('C.R Sem. 2026'!D287,'C.R Sem. 2026'!D276,'C.R Sem. 2026'!D265,'C.R Sem. 2026'!D254,'C.R Sem. 2026'!D243) -> 62 | E37: =SUM('C.R Sem. 2026'!E287,'C.R Sem. 2026'!E276,'C.R Sem. 2026'!E265,'C.R Sem. 2026'!E254,'C.R Sem. 2026'!E243) -> 56 | F37: =SUM('C.R Sem. 2026'!F287,'C.R Sem. 2026'!F276,'C.R Sem. 2026'!F265,'C.R Sem. 2026'!F254,'C.R Sem. 2026'!F243) -> 0
A38: Juillet | B38: Oui | H38: =IF(G38>'C.R Mois 2025'!K32,"↑",IF(G38<'C.R Mois 2025'!K32,"↓","→")) -> ↓ | I38: =G38-'C.R Mois 2025'!K32 -> -61 | J38: =(G38-'C.R Mois 2025'!K32)/'C.R Mois 2025'!K32 -> -1
B39: Oui OF
B40: À réfléchir
...

Sheet C.R Mois 2025
A1: Période | B1: Catégorie | C1: Amanda | D1: Emile | E1: Brandon | F1: Immersion | G1: Elsa | H1: Laureen-Lee | I1: Brice | J1: Lamia | K1: Total 2025
A2: Janvier | B2: Oui | C2: =SUM('C.R Sem. 2025'!C2+'C.R Sem. 2025'!C11+'C.R Sem. 2025'!C20+'C.R Sem. 2025'!C29) -> 8 | D2: =SUM('C.R Sem. 2025'!D2+'C.R Sem. 2025'!D11+'C.R Sem. 2025'!D20+'C.R Sem. 2025'!D29) -> 0 | E2: =SUM('C.R Sem. 2025'!E2+'C.R Sem. 2025'!E11+'C.R Sem. 2025'!E20+'C.R Sem. 2025'!E29) -> 0 | F2: =SUM('C.R Sem. 2025'!F2+'C.R Sem. 2025'!F11+'C.R Sem. 2025'!F20+'C.R Sem. 2025'!F29) -> 0 | G2: =SUM('C.R Sem. 2025'!G2+'C.R Sem. 2025'!G11+'C.R Sem. 2025'!G20+'C.R Sem. 2025'!G29) -> 0 | H2: =SUM('C.R Sem. 2025'!H2+'C.R Sem. 2025'!H11+'C.R Sem. 2025'!H20+'C.R Sem. 2025'!H29) -> 0 | I2: =SUM('C.R Sem. 2025'!I2+'C.R Sem. 2025'!I11+'C.R Sem. 2025'!I20+'C.R Sem. 2025'!I29) -> 6 | J2: =SUM('C.R Sem. 2025'!J2+'C.R Sem. 2025'!J11+'C.R Sem. 2025'!J20+'C.R Sem. 2025'!J29) -> 3 | K2: =SUM(C2:J2) -> 17 | L2: Nouveaux clients
B3: À réfléchir | C3: =SUM('C.R Sem. 2025'!C5+'C.R Sem. 2025'!C14+'C.R Sem. 2025'!C23+'C.R Sem. 2025'!C32) -> 100 | D3: =SUM('C.R Sem. 2025'!D5+'C.R Sem. 2025'!D14+'C.R Sem. 2025'!D23+'C.R Sem. 2025'!D32) -> 0 | E3: =SUM('C.R Sem. 2025'!E5+'C.R Sem. 2025'!E14+'C.R Sem. 2025'!E23+'C.R Sem. 2025'!E32) -> 0 | F3: =SUM('C.R Sem. 2025'!F5+'C.R Sem. 2025'!F14+'C.R Sem. 2025'!F23+'C.R Sem. 2025'!F32) -> 0 | G3: =SUM('C.R Sem. 2025'!G5+'C.R Sem. 2025'!G14+'C.R Sem. 2025'!G23+'C.R Sem. 2025'!G32) -> 0 | H3: =SUM('C.R Sem. 2025'!H5+'C.R Sem. 2025'!H14+'C.R Sem. 2025'!H23+'C.R Sem. 2025'!H32) -> 0 | I3: =SUM('C.R Sem. 2025'!I5+'C.R Sem. 2025'!I14+'C.R Sem. 2025'!I23+'C.R Sem. 2025'!I32) -> 18 | J3: =SUM('C.R Sem. 2025'!J5+'C.R Sem. 2025'!J14+'C.R Sem. 2025'!J23+'C.R Sem. 2025'!J32) -> 31 | M3: Non employé
B4: Total d'appel | C4: =SUM('C.R Sem. 2025'!C7+'C.R Sem. 2025'!C16+'C.R Sem. 2025'!C25+'C.R Sem. 2025'!C34) -> 406 | D4: =SUM('C.R Sem. 2025'!D7+'C.R Sem. 2025'!D16+'C.R Sem. 2025'!D25+'C.R Sem. 2025'!D34) -> 0 | E4: =SUM('C.R Sem. 2025'!E7+'C.R Sem. 2025'!E16+'C.R Sem. 2025'!E25+'C.R Sem. 2025'!E34) -> 0 | F4: =SUM('C.R Sem. 2025'!F7+'C.R Sem. 2025'!F16+'C.R Sem. 2025'!F25+'C.R Sem. 2025'!F34) -> 0 | G4: =SUM('C.R Sem. 2025'!G7+'C.R Sem. 2025'!G16+'C.R Sem. 2025'!G25+'C.R Sem. 2025'!G34) -> 0 | H4: =SUM('C.R Sem. 2025'!H7+'C.R Sem. 2025'!H16+'C.R Sem. 2025'!H25+'C.R Sem. 2025'!H34) -> 0 | I4: =SUM('C.R Sem. 2025'!I7+'C.R Sem. 2025'!I16+'C.R Sem. 2025'!I25+'C.R Sem. 2025'!I34) -> 323 | J4: =SUM('C.R Sem. 2025'!J7+'C.R Sem. 2025'!J16+'C.R Sem. 2025'!J25+'C.R Sem. 2025'!J34) -> 332
B5: Total trier | C5: =SUM('C.R Sem. 2025'!C8+'C.R Sem. 2025'!C17+'C.R Sem. 2025'!C26+'C.R Sem. 2025'!C35) -> 932 | D5: =SUM('C.R Sem. 2025'!D8+'C.R Sem. 2025'!D17+'C.R Sem. 2025'!D26+'C.R Sem. 2025'!D35) -> 0 | E5: =SUM('C.R Sem. 2025'!E8+'C.R Sem. 2025'!E17+'C.R Sem. 2025'!E26+'C.R Sem. 2025'!E35) -> 0 | F5: =SUM('C.R Sem. 2025'!F8+'C.R Sem. 2025'!F17+'C.R Sem. 2025'!F26+'C.R Sem. 2025'!F35) -> 0 | G5: =SUM('C.R Sem. 2025'!G8+'C.R Sem. 2025'!G17+'C.R Sem. 2025'!G26+'C.R Sem. 2025'!G35) -> 0 | H5: =SUM('C.R Sem. 2025'!H8+'C.R Sem. 2025'!H17+'C.R Sem. 2025'!H26+'C.R Sem. 2025'!H35) -> 0 | I5: =SUM('C.R Sem. 2025'!I8+'C.R Sem. 2025'!I17+'C.R Sem. 2025'!I26+'C.R Sem. 2025'!I35) -> 646 | J5: =SUM('C.R Sem. 2025'!J8+'C.R Sem. 2025'!J17+'C.R Sem. 2025'!J26+'C.R Sem. 2025'!J35) -> 784
B6: Nbre d'ent. ouvert | C6: =SUM('C.R Sem. 2025'!C10+'C.R Sem. 2025'!C19+'C.R Sem. 2025'!C28+'C.R Sem. 2025'!C37) -> 566 | D6: =SUM('C.R Sem. 2025'!D10+'C.R Sem. 2025'!D19+'C.R Sem. 2025'!D28+'C.R Sem. 2025'!D37) -> 0 | E6: =SUM('C.R Sem. 2025'!E10+'C.R Sem. 2025'!E19+'C.R Sem. 2025'!E28+'C.R Sem. 2025'!E37) -> 0 | F6: =SUM('C.R Sem. 2025'!F10+'C.R Sem. 2025'!F19+'C.R Sem. 2025'!F28+'C.R Sem. 2025'!F37) -> 0 | G6: =SUM('C.R Sem. 2025'!G10+'C.R Sem. 2025'!G19+'C.R Sem. 2025'!G28+'C.R Sem. 2025'!G37) -> 0 | H6: =SUM('C.R Sem. 2025'!H10+'C.R Sem. 2025'!H19+'C.R Sem. 2025'!H28+'C.R Sem. 2025'!H37) -> 0 | I6: =SUM('C.R Sem. 2025'!I10+'C.R Sem. 2025'!I19+'C.R Sem. 2025'!I28+'C.R Sem. 2025'!I37) -> 263 | J6: =SUM('C.R Sem. 2025'!J10+'C.R Sem. 2025'!J19+'C.R Sem. 2025'!J28+'C.R Sem. 2025'!J37) -> 398
A7: Février | B7: Oui | C7: =SUM('C.R Sem. 2025'!C38+'C.R Sem. 2025'!C47+'C.R Sem. 2025'!C56+'C.R Sem. 2025'!C65) -> 19 | D7: =SUM('C.R Sem. 2025'!D38+'C.R Sem. 2025'!D47+'C.R Sem. 2025'!D56+'C.R Sem. 2025'!D65) -> 0 | E7: =SUM('C.R Sem. 2025'!E38+'C.R Sem. 2025'!E47+'C.R Sem. 2025'!E56+'C.R Sem. 2025'!E65) -> 0 | F7: =SUM('C.R Sem. 2025'!F38+'C.R Sem. 2025'!F47+'C.R Sem. 2025'!F56+'C.R Sem. 2025'!F65) -> 0 | G7: =SUM('C.R Sem. 2025'!G38+'C.R Sem. 2025'!G47+'C.R Sem. 2025'!G56+'C.R Sem. 2025'!G65) -> 0 | H7: =SUM('C.R Sem. 2025'!H38+'C.R Sem. 2025'!H47+'C.R Sem. 2025'!H56+'C.R Sem. 2025'!H65) -> 0 | I7: =SUM('C.R Sem. 2025'!I38+'C.R Sem. 2025'!I47+'C.R Sem. 2025'!I56+'C.R Sem. 2025'!I65) -> 7 | J7: =SUM('C.R Sem. 2025'!J38+'C.R Sem. 2025'!J47+'C.R Sem. 2025'!J56+'C.R Sem. 2025'!J65) -> 12 | K7: =SUM(C7:J7) -> 38 | L7: Nouveaux contrats
B8: À réfléchir | C8: =SUM('C.R Sem. 2025'!C41+'C.R Sem. 2025'!C50+'C.R Sem. 2025'!C59+'C.R Sem. 2025'!C68) -> 62 | D8: =SUM('C.R Sem. 2025'!D41+'C.R Sem. 2025'!D50+'C.R Sem. 2025'!D59+'C.R Sem. 2025'!D68) -> 0 | E8: =SUM('C.R Sem. 2025'!E41+'C.R Sem. 2025'!E50+'C.R Sem. 2025'!E59+'C.R Sem. 2025'!E68) -> 0 | F8: =SUM('C.R Sem. 2025'!F41+'C.R Sem. 2025'!F50+'C.R Sem. 2025'!F59+'C.R Sem. 2025'!F68) -> 0 | G8: =SUM('C.R Sem. 2025'!G41+'C.R Sem. 2025'!G50+'C.R Sem. 2025'!G59+'C.R Sem. 2025'!G68) -> 0 | H8: =SUM('C.R Sem. 2025'!H41+'C.R Sem. 2025'!H50+'C.R Sem. 2025'!H59+'C.R Sem. 2025'!H68) -> 0 | I8: =SUM('C.R Sem. 2025'!I41+'C.R Sem. 2025'!I50+'C.R Sem. 2025'!I59+'C.R Sem. 2025'!I68) -> 28 | J8: =SUM('C.R Sem. 2025'!J41+'C.R Sem. 2025'!J50+'C.R Sem. 2025'!J59+'C.R Sem. 2025'!J68) -> 35
B9: Total d'appel | C9: =SUM('C.R Sem. 2025'!C43+'C.R Sem. 2025'!C52+'C.R Sem. 2025'!C61+'C.R Sem. 2025'!C70) -> 317 | D9: =SUM('C.R Sem. 2025'!D43+'C.R Sem. 2025'!D52+'C.R Sem. 2025'!D61+'C.R Sem. 2025'!D70) -> 0 | E9: =SUM('C.R Sem. 2025'!E43+'C.R Sem. 2025'!E52+'C.R Sem. 2025'!E61+'C.R Sem. 2025'!E70) -> 0 | F9: =SUM('C.R Sem. 2025'!F43+'C.R Sem. 2025'!F52+'C.R Sem. 2025'!F61+'C.R Sem. 2025'!F70) -> 0 | G9: =SUM('C.R Sem. 2025'!G43+'C.R Sem. 2025'!G52+'C.R Sem. 2025'!G61+'C.R Sem. 2025'!G70) -> 0 | H9: =SUM('C.R Sem. 2025'!H43+'C.R Sem. 2025'!H52+'C.R Sem. 2025'!H61+'C.R Sem. 2025'!H70) -> 0 | I9: =SUM('C.R Sem. 2025'!I43+'C.R Sem. 2025'!I52+'C.R Sem. 2025'!I61+'C.R Sem. 2025'!I70) -> 331 | J9: =SUM('C.R Sem. 2025'!J43+'C.R Sem. 2025'!J52+'C.R Sem. 2025'!J61+'C.R Sem. 2025'!J70) -> 275
B10: Total trier | C10: =SUM('C.R Sem. 2025'!C44+'C.R Sem. 2025'!C53+'C.R Sem. 2025'!C62+'C.R Sem. 2025'!C71) -> 665 | D10: =SUM('C.R Sem. 2025'!D44+'C.R Sem. 2025'!D53+'C.R Sem. 2025'!D62+'C.R Sem. 2025'!D71) -> 0 | E10: =SUM('C.R Sem. 2025'!E44+'C.R Sem. 2025'!E53+'C.R Sem. 2025'!E62+'C.R Sem. 2025'!E71) -> 0 | F10: =SUM('C.R Sem. 2025'!F44+'C.R Sem. 2025'!F53+'C.R Sem. 2025'!F62+'C.R Sem. 2025'!F71) -> 0 | G10: =SUM('C.R Sem. 2025'!G44+'C.R Sem. 2025'!G53+'C.R Sem. 2025'!G62+'C.R Sem. 2025'!G71) -> 0 | H10: =SUM('C.R Sem. 2025'!H44+'C.R Sem. 2025'!H53+'C.R Sem. 2025'!H62+'C.R Sem. 2025'!H71) -> 0 | I10: =SUM('C.R Sem. 2025'!I44+'C.R Sem. 2025'!I53+'C.R Sem. 2025'!I62+'C.R Sem. 2025'!I71) -> 602 | J10: =SUM('C.R Sem. 2025'!J44+'C.R Sem. 2025'!J53+'C.R Sem. 2025'!J62+'C.R Sem. 2025'!J71) -> 761
B11: Nbre d'ent. ouvert | C11: =SUM('C.R Sem. 2025'!C46+'C.R Sem. 2025'!C55+'C.R Sem. 2025'!C64+'C.R Sem. 2025'!C73) -> 385 | D11: =SUM('C.R Sem. 2025'!D46+'C.R Sem. 2025'!D55+'C.R Sem. 2025'!D64+'C.R Sem. 2025'!D73) -> 0 | E11: =SUM('C.R Sem. 2025'!E46+'C.R Sem. 2025'!E55+'C.R Sem. 2025'!E64+'C.R Sem. 2025'!E73) -> 0 | F11: =SUM('C.R Sem. 2025'!F46+'C.R Sem. 2025'!F55+'C.R Sem. 2025'!F64+'C.R Sem. 2025'!F73) -> 0 | G11: =SUM('C.R Sem. 2025'!G46+'C.R Sem. 2025'!G55+'C.R Sem. 2025'!G64+'C.R Sem. 2025'!G73) -> 0 | H11: =SUM('C.R Sem. 2025'!H46+'C.R Sem. 2025'!H55+'C.R Sem. 2025'!H64+'C.R Sem. 2025'!H73) -> 0 | I11: =SUM('C.R Sem. 2025'!I46+'C.R Sem. 2025'!I55+'C.R Sem. 2025'!I64+'C.R Sem. 2025'!I73) -> 299 | J11: =SUM('C.R Sem. 2025'!J46+'C.R Sem. 2025'!J55+'C.R Sem. 2025'!J64+'C.R Sem. 2025'!J73) -> 412
A12: Mars | B12: Oui | C12: =SUM('C.R Sem. 2025'!C74+'C.R Sem. 2025'!C83+'C.R Sem. 2025'!C92+'C.R Sem. 2025'!C101) -> 28 | D12: =SUM('C.R Sem. 2025'!D74+'C.R Sem. 2025'!D83+'C.R Sem. 2025'!D92+'C.R Sem. 2025'!D101) -> 0 | E12: =SUM('C.R Sem. 2025'!E74+'C.R Sem. 2025'!E83+'C.R Sem. 2025'!E92+'C.R Sem. 2025'!E101) -> 0 | F12: =SUM('C.R Sem. 2025'!F74+'C.R Sem. 2025'!F83+'C.R Sem. 2025'!F92+'C.R Sem. 2025'!F101) -> 0 | G12: =SUM('C.R Sem. 2025'!G74+'C.R Sem. 2025'!G83+'C.R Sem. 2025'!G92+'C.R Sem. 2025'!G101) -> 0 | H12: =SUM('C.R Sem. 2025'!H74+'C.R Sem. 2025'!H83+'C.R Sem. 2025'!H92+'C.R Sem. 2025'!H101) -> 0 | I12: =SUM('C.R Sem. 2025'!I74+'C.R Sem. 2025'!I83+'C.R Sem. 2025'!I92+'C.R Sem. 2025'!I101) -> 28 | J12: =SUM('C.R Sem. 2025'!J74+'C.R Sem. 2025'!J83+'C.R Sem. 2025'!J92+'C.R Sem. 2025'!J101) -> 19 | K12: =SUM(C12:J12) -> 75 | L12: Nouveaux contrats
B13: À réfléchir | C13: ='C.R Sem. 2025'!C77+'C.R Sem. 2025'!C86+'C.R Sem. 2025'!C95+'C.R Sem. 2025'!C104 -> 59 | D13: ='C.R Sem. 2025'!D77+'C.R Sem. 2025'!D86+'C.R Sem. 2025'!D95+'C.R Sem. 2025'!D104 -> 0 | E13: ='C.R Sem. 2025'!E77+'C.R Sem. 2025'!E86+'C.R Sem. 2025'!E95+'C.R Sem. 2025'!E104 -> 0 | F13: ='C.R Sem. 2025'!F77+'C.R Sem. 2025'!F86+'C.R Sem. 2025'!F95+'C.R Sem. 2025'!F104 -> 0 | G13: ='C.R Sem. 2025'!G77+'C.R Sem. 2025'!G86+'C.R Sem. 2025'!G95+'C.R Sem. 2025'!G104 -> 0 | H13: ='C.R Sem. 2025'!H77+'C.R Sem. 2025'!H86+'C.R Sem. 2025'!H95+'C.R Sem. 2025'!H104 -> 0 | I13: ='C.R Sem. 2025'!I77+'C.R Sem. 2025'!I86+'C.R Sem. 2025'!I95+'C.R Sem. 2025'!I104 -> 19 | J13: ='C.R Sem. 2025'!J77+'C.R Sem. 2025'!J86+'C.R Sem. 2025'!J95+'C.R Sem. 2025'!J104 -> 42
B14: Total d'appel | C14: =SUM('C.R Sem. 2025'!C79+'C.R Sem. 2025'!C88+'C.R Sem. 2025'!C97+'C.R Sem. 2025'!C106) -> 423 | D14: =SUM('C.R Sem. 2025'!D79+'C.R Sem. 2025'!D88+'C.R Sem. 2025'!D97+'C.R Sem. 2025'!D106) -> 0 | E14: =SUM('C.R Sem. 2025'!E79+'C.R Sem. 2025'!E88+'C.R Sem. 2025'!E97+'C.R Sem. 2025'!E106) -> 0 | F14: =SUM('C.R Sem. 2025'!F79+'C.R Sem. 2025'!F88+'C.R Sem. 2025'!F97+'C.R Sem. 2025'!F106) -> 0 | G14: =SUM('C.R Sem. 2025'!G79+'C.R Sem. 2025'!G88+'C.R Sem. 2025'!G97+'C.R Sem. 2025'!G106) -> 0 | H14: =SUM('C.R Sem. 2025'!H79+'C.R Sem. 2025'!H88+'C.R Sem. 2025'!H97+'C.R Sem. 2025'!H106) -> 0 | I14: =SUM('C.R Sem. 2025'!I79+'C.R Sem. 2025'!I88+'C.R Sem. 2025'!I97+'C.R Sem. 2025'!I106) -> 491 | J14: =SUM('C.R Sem. 2025'!J79+'C.R Sem. 2025'!J88+'C.R Sem. 2025'!J97+'C.R Sem. 2025'!J106) -> 373
B15: Total trier | C15: ='C.R Sem. 2025'!C80+'C.R Sem. 2025'!C89+'C.R Sem. 2025'!C107+'C.R Sem. 2025'!C116 -> 657 | D15: ='C.R Sem. 2025'!D80+'C.R Sem. 2025'!D89+'C.R Sem. 2025'!D107+'C.R Sem. 2025'!D116 -> 0 | E15: ='C.R Sem. 2025'!E80+'C.R Sem. 2025'!E89+'C.R Sem. 2025'!E107+'C.R Sem. 2025'!E116 -> 0 | F15: ='C.R Sem. 2025'!F80+'C.R Sem. 2025'!F89+'C.R Sem. 2025'!F107+'C.R Sem. 2025'!F116 -> 0 | G15: ='C.R Sem. 2025'!G80+'C.R Sem. 2025'!G89+'C.R Sem. 2025'!G107+'C.R Sem. 2025'!G116 -> 0 | H15: ='C.R Sem. 2025'!H80+'C.R Sem. 2025'!H89+'C.R Sem. 2025'!H107+'C.R Sem. 2025'!H116 -> 0 | I15: ='C.R Sem. 2025'!I80+'C.R Sem. 2025'!I89+'C.R Sem. 2025'!I107+'C.R Sem. 2025'!I116 -> 550 | J15: ='C.R Sem. 2025'!J80+'C.R Sem. 2025'!J89+'C.R Sem. 2025'!J107+'C.R Sem. 2025'!J116 -> 558
B16: Nbre d'ent. ouvert | C16: =SUM('C.R Sem. 2025'!C82+'C.R Sem. 2025'!C91+'C.R Sem. 2025'!C100+'C.R Sem. 2025'!C109) -> 547 | D16: =SUM('C.R Sem. 2025'!D82+'C.R Sem. 2025'!D91+'C.R Sem. 2025'!D100+'C.R Sem. 2025'!D109) -> 0 | E16: =SUM('C.R Sem. 2025'!E82+'C.R Sem. 2025'!E91+'C.R Sem. 2025'!E100+'C.R Sem. 2025'!E109) -> 0 | F16: =SUM('C.R Sem. 2025'!F82+'C.R Sem. 2025'!F91+'C.R Sem. 2025'!F100+'C.R Sem. 2025'!F109) -> 0 | G16: =SUM('C.R Sem. 2025'!G82+'C.R Sem. 2025'!G91+'C.R Sem. 2025'!G100+'C.R Sem. 2025'!G109) -> 0 | H16: =SUM('C.R Sem. 2025'!H82+'C.R Sem. 2025'!H91+'C.R Sem. 2025'!H100+'C.R Sem. 2025'!H109) -> 0 | I16: =SUM('C.R Sem. 2025'!I82+'C.R Sem. 2025'!I91+'C.R Sem. 2025'!I100+'C.R Sem. 2025'!I109) -> 485 | J16: =SUM('C.R Sem. 2025'!J82+'C.R Sem. 2025'!J91+'C.R Sem. 2025'!J100+'C.R Sem. 2025'!J109) -> 423
A17: Avril | B17: Oui | C17: =SUM('C.R Sem. 2025'!C110+'C.R Sem. 2025'!C119+'C.R Sem. 2025'!C128+'C.R Sem. 2025'!C137+'C.R Sem. 2025'!C146) -> 20 | D17: =SUM('C.R Sem. 2025'!D110+'C.R Sem. 2025'!D119+'C.R Sem. 2025'!D128+'C.R Sem. 2025'!D137+'C.R Sem. 2025'!D146) -> 0 | E17: =SUM('C.R Sem. 2025'!E110+'C.R Sem. 2025'!E119+'C.R Sem. 2025'!E128+'C.R Sem. 2025'!E137+'C.R Sem. 2025'!E146) -> 0 | F17: =SUM('C.R Sem. 2025'!F110+'C.R Sem. 2025'!F119+'C.R Sem. 2025'!F128+'C.R Sem. 2025'!F137+'C.R Sem. 2025'!F146) -> 0 | G17: =SUM('C.R Sem. 2025'!G110+'C.R Sem. 2025'!G119+'C.R Sem. 2025'!G128+'C.R Sem. 2025'!G137+'C.R Sem. 2025'!G146) -> 0 | H17: =SUM('C.R Sem. 2025'!H110+'C.R Sem. 2025'!H119+'C.R Sem. 2025'!H128+'C.R Sem. 2025'!H137+'C.R Sem. 2025'!H146) -> 0 | I17: =SUM('C.R Sem. 2025'!I110+'C.R Sem. 2025'!I119+'C.R Sem. 2025'!I128+'C.R Sem. 2025'!I137+'C.R Sem. 2025'!I146) -> 7 | J17: =SUM('C.R Sem. 2025'!J110+'C.R Sem. 2025'!J119+'C.R Sem. 2025'!J128+'C.R Sem. 2025'!J137+'C.R Sem. 2025'!J146) -> 8 | K17: =SUM(C17:J17) -> 35 | L17: Nouveaux contrats
B18: À réfléchir | C18: =SUM('C.R Sem. 2025'!C113+'C.R Sem. 2025'!C122+'C.R Sem. 2025'!C131+'C.R Sem. 2025'!C140+'C.R Sem. 2025'!C149) -> 48 | D18: =SUM('C.R Sem. 2025'!D113+'C.R Sem. 2025'!D122+'C.R Sem. 2025'!D131+'C.R Sem. 2025'!D140+'C.R Sem. 2025'!D149) -> 0 | E18: =SUM('C.R Sem. 2025'!E113+'C.R Sem. 2025'!E122+'C.R Sem. 2025'!E131+'C.R Sem. 2025'!E140+'C.R Sem. 2025'!E149) -> 0 | F18: =SUM('C.R Sem. 2025'!F113+'C.R Sem. 2025'!F122+'C.R Sem. 2025'!F131+'C.R Sem. 2025'!F140+'C.R Sem. 2025'!F149) -> 0 | G18: =SUM('C.R Sem. 2025'!G113+'C.R Sem. 2025'!G122+'C.R Sem. 2025'!G131+'C.R Sem. 2025'!G140+'C.R Sem. 2025'!G149) -> 0 | H18: =SUM('C.R Sem. 2025'!H113+'C.R Sem. 2025'!H122+'C.R Sem. 2025'!H131+'C.R Sem. 2025'!H140+'C.R Sem. 2025'!H149) -> 0 | I18: =SUM('C.R Sem. 2025'!I113+'C.R Sem. 2025'!I122+'C.R Sem. 2025'!I131+'C.R Sem. 2025'!I140+'C.R Sem. 2025'!I149) -> 20 | J18: =SUM('C.R Sem. 2025'!J113+'C.R Sem. 2025'!J122+'C.R Sem. 2025'!J131+'C.R Sem. 2025'!J140+'C.R Sem. 2025'!J149) -> 39
B19: Total d'appel | C19: =SUM('C.R Sem. 2025'!C115+'C.R Sem. 2025'!C124+'C.R Sem. 2025'!C133+'C.R Sem. 2025'!C142+'C.R Sem. 2025'!C151) -> 376 | D19: =SUM('C.R Sem. 2025'!D115+'C.R Sem. 2025'!D124+'C.R Sem. 2025'!D133+'C.R Sem. 2025'!D142+'C.R Sem. 2025'!D151) -> 0 | E19: =SUM('C.R Sem. 2025'!E115+'C.R Sem. 2025'!E124+'C.R Sem. 2025'!E133+'C.R Sem. 2025'!E142+'C.R Sem. 2025'!E151) -> 0 | F19: =SUM('C.R Sem. 2025'!F115+'C.R Sem. 2025'!F124+'C.R Sem. 2025'!F133+'C.R Sem. 2025'!F142+'C.R Sem. 2025'!F151) -> 0 | G19: =SUM('C.R Sem. 2025'!G115+'C.R Sem. 2025'!G124+'C.R Sem. 2025'!G133+'C.R Sem. 2025'!G142+'C.R Sem. 2025'!G151) -> 0 | H19: =SUM('C.R Sem. 2025'!H115+'C.R Sem. 2025'!H124+'C.R Sem. 2025'!H133+'C.R Sem. 2025'!H142+'C.R Sem. 2025'!H151) -> 0 | I19: =SUM('C.R Sem. 2025'!I115+'C.R Sem. 2025'!I124+'C.R Sem. 2025'!I133+'C.R Sem. 2025'!I142+'C.R Sem. 2025'!I151) -> 517 | J19: =SUM('C.R Sem. 2025'!J115+'C.R Sem. 2025'!J124+'C.R Sem. 2025'!J133+'C.R Sem. 2025'!J142+'C.R Sem. 2025'!J151) -> 439
B20: Total trier | C20: =SUM('C.R Sem. 2025'!C116+'C.R Sem. 2025'!C125+'C.R Sem. 2025'!C134+'C.R Sem. 2025'!C143+'C.R Sem. 2025'!C152) -> 624 | D20: =SUM('C.R Sem. 2025'!D116+'C.R Sem. 2025'!D125+'C.R Sem. 2025'!D134+'C.R Sem. 2025'!D143+'C.R Sem. 2025'!D152) -> 0 | E20: =SUM('C.R Sem. 2025'!E116+'C.R Sem. 2025'!E125+'C.R Sem. 2025'!E134+'C.R Sem. 2025'!E143+'C.R Sem. 2025'!E152) -> 0 | F20: =SUM('C.R Sem. 2025'!F116+'C.R Sem. 2025'!F125+'C.R Sem. 2025'!F134+'C.R Sem. 2025'!F143+'C.R Sem. 2025'!F152) -> 0 | G20: =SUM('C.R Sem. 2025'!G116+'C.R Sem. 2025'!G125+'C.R Sem. 2025'!G134+'C.R Sem. 2025'!G143+'C.R Sem. 2025'!G152) -> 0 | H20: =SUM('C.R Sem. 2025'!H116+'C.R Sem. 2025'!H125+'C.R Sem. 2025'!H134+'C.R Sem. 2025'!H143+'C.R Sem. 2025'!H152) -> 0 | I20: =SUM('C.R Sem. 2025'!I116+'C.R Sem. 2025'!I125+'C.R Sem. 2025'!I134+'C.R Sem. 2025'!I143+'C.R Sem. 2025'!I152) -> 566 | J20: =SUM('C.R Sem. 2025'!J116+'C.R Sem. 2025'!J125+'C.R Sem. 2025'!J134+'C.R Sem. 2025'!J143+'C.R Sem. 2025'!J152) -> 544
B21: Nbre d'ent. ouvert | C21: =SUM('C.R Sem. 2025'!C118+'C.R Sem. 2025'!C127+'C.R Sem. 2025'!C136+'C.R Sem. 2025'!C145+'C.R Sem. 2025'!C154) -> 605 | D21: =SUM('C.R Sem. 2025'!D118+'C.R Sem. 2025'!D127+'C.R Sem. 2025'!D136+'C.R Sem. 2025'!D145+'C.R Sem. 2025'!D154) -> 0 | E21: =SUM('C.R Sem. 2025'!E118+'C.R Sem. 2025'!E127+'C.R Sem. 2025'!E136+'C.R Sem. 2025'!E145+'C.R Sem. 2025'!E154) -> 0 | F21: =SUM('C.R Sem. 2025'!F118+'C.R Sem. 2025'!F127+'C.R Sem. 2025'!F136+'C.R Sem. 2025'!F145+'C.R Sem. 2025'!F154) -> 0 | G21: =SUM('C.R Sem. 2025'!G118+'C.R Sem. 2025'!G127+'C.R Sem. 2025'!G136+'C.R Sem. 2025'!G145+'C.R Sem. 2025'!G154) -> 0 | H21: =SUM('C.R Sem. 2025'!H118+'C.R Sem. 2025'!H127+'C.R Sem. 2025'!H136+'C.R Sem. 2025'!H145+'C.R Sem. 2025'!H154) -> 0 | I21: =SUM('C.R Sem. 2025'!I118+'C.R Sem. 2025'!I127+'C.R Sem. 2025'!I136+'C.R Sem. 2025'!I145+'C.R Sem. 2025'!I154) -> 396 | J21: =SUM('C.R Sem. 2025'!J118+'C.R Sem. 2025'!J127+'C.R Sem. 2025'!J136+'C.R Sem. 2025'!J145+'C.R Sem. 2025'!J154) -> 517
A22: Mai | B22: Oui | C22: =SUM('C.R Sem. 2025'!C155+'C.R Sem. 2025'!C164+'C.R Sem. 2025'!C173+'C.R Sem. 2025'!C182) -> 28 | D22: =SUM('C.R Sem. 2025'!D155+'C.R Sem. 2025'!D164+'C.R Sem. 2025'!D173+'C.R Sem. 2025'!D182) -> 0 | E22: =SUM('C.R Sem. 2025'!E155+'C.R Sem. 2025'!E164+'C.R Sem. 2025'!E173+'C.R Sem. 2025'!E182) -> 0 | F22: =SUM('C.R Sem. 2025'!F155+'C.R Sem. 2025'!F164+'C.R Sem. 2025'!F173+'C.R Sem. 2025'!F182) -> 0 | G22: =SUM('C.R Sem. 2025'!G155+'C.R Sem. 2025'!G164+'C.R Sem. 2025'!G173+'C.R Sem. 2025'!G182) -> 0 | H22: =SUM('C.R Sem. 2025'!H155+'C.R Sem. 2025'!H164+'C.R Sem. 2025'!H173+'C.R Sem. 2025'!H182) -> 0 | I22: =SUM('C.R Sem. 2025'!I155+'C.R Sem. 2025'!I164+'C.R Sem. 2025'!I173+'C.R Sem. 2025'!I182) -> 17 | J22: =SUM('C.R Sem. 2025'!J155+'C.R Sem. 2025'!J164+'C.R Sem. 2025'!J173+'C.R Sem. 2025'!J182) -> 8 | K22: =SUM(C22:J22) -> 53 | L22: Nouveaux contrats
B23: À réfléchir | C23: =SUM('C.R Sem. 2025'!C158+'C.R Sem. 2025'!C176+'C.R Sem. 2025'!C185+'C.R Sem. 2025'!C195) -> 40 | D23: =SUM('C.R Sem. 2025'!D158+'C.R Sem. 2025'!D176+'C.R Sem. 2025'!D185+'C.R Sem. 2025'!D195) -> 0 | E23: =SUM('C.R Sem. 2025'!E158+'C.R Sem. 2025'!E176+'C.R Sem. 2025'!E185+'C.R Sem. 2025'!E195) -> 0 | F23: =SUM('C.R Sem. 2025'!F158+'C.R Sem. 2025'!F176+'C.R Sem. 2025'!F185+'C.R Sem. 2025'!F195) -> 0 | G23: =SUM('C.R Sem. 2025'!G158+'C.R Sem. 2025'!G176+'C.R Sem. 2025'!G185+'C.R Sem. 2025'!G195) -> 0 | H23: =SUM('C.R Sem. 2025'!H158+'C.R Sem. 2025'!H176+'C.R Sem. 2025'!H185+'C.R Sem. 2025'!H195) -> 0 | I23: =SUM('C.R Sem. 2025'!I158+'C.R Sem. 2025'!I176+'C.R Sem. 2025'!I185+'C.R Sem. 2025'!I195) -> 49 | J23: =SUM('C.R Sem. 2025'!J158+'C.R Sem. 2025'!J176+'C.R Sem. 2025'!J185+'C.R Sem. 2025'!J195) -> 33
B24: Total d'appel | C24: =SUM('C.R Sem. 2025'!C160+'C.R Sem. 2025'!C169+'C.R Sem. 2025'!C178+'C.R Sem. 2025'!C187) -> 145 | D24: =SUM('C.R Sem. 2025'!D160+'C.R Sem. 2025'!D169+'C.R Sem. 2025'!D178+'C.R Sem. 2025'!D187) -> 0 | E24: =SUM('C.R Sem. 2025'!E160+'C.R Sem. 2025'!E169+'C.R Sem. 2025'!E178+'C.R Sem. 2025'!E187) -> 0 | F24: =SUM('C.R Sem. 2025'!F160+'C.R Sem. 2025'!F169+'C.R Sem. 2025'!F178+'C.R Sem. 2025'!F187) -> 0 | G24: =SUM('C.R Sem. 2025'!G160+'C.R Sem. 2025'!G169+'C.R Sem. 2025'!G178+'C.R Sem. 2025'!G187) -> 0 | H24: =SUM('C.R Sem. 2025'!H160+'C.R Sem. 2025'!H169+'C.R Sem. 2025'!H178+'C.R Sem. 2025'!H187) -> 0 | I24: =SUM('C.R Sem. 2025'!I160+'C.R Sem. 2025'!I169+'C.R Sem. 2025'!I178+'C.R Sem. 2025'!I187) -> 277 | J24: =SUM('C.R Sem. 2025'!J160+'C.R Sem. 2025'!J169+'C.R Sem. 2025'!J178+'C.R Sem. 2025'!J187) -> 335
B25: Total trier | C25: =SUM('C.R Sem. 2025'!C161+'C.R Sem. 2025'!C170+'C.R Sem. 2025'!C179+'C.R Sem. 2025'!C188) -> 165 | D25: =SUM('C.R Sem. 2025'!D161+'C.R Sem. 2025'!D170+'C.R Sem. 2025'!D179+'C.R Sem. 2025'!D188) -> 0 | E25: =SUM('C.R Sem. 2025'!E161+'C.R Sem. 2025'!E170+'C.R Sem. 2025'!E179+'C.R Sem. 2025'!E188) -> 0 | F25: =SUM('C.R Sem. 2025'!F161+'C.R Sem. 2025'!F170+'C.R Sem. 2025'!F179+'C.R Sem. 2025'!F188) -> 0 | G25: =SUM('C.R Sem. 2025'!G161+'C.R Sem. 2025'!G170+'C.R Sem. 2025'!G179+'C.R Sem. 2025'!G188) -> 0 | H25: =SUM('C.R Sem. 2025'!H161+'C.R Sem. 2025'!H170+'C.R Sem. 2025'!H179+'C.R Sem. 2025'!H188) -> 0 | I25: =SUM('C.R Sem. 2025'!I161+'C.R Sem. 2025'!I170+'C.R Sem. 2025'!I179+'C.R Sem. 2025'!I188) -> 291 | J25: =SUM('C.R Sem. 2025'!J161+'C.R Sem. 2025'!J170+'C.R Sem. 2025'!J179+'C.R Sem. 2025'!J188) -> 364
B26: Nbre d'ent. ouvert | C26: =SUM('C.R Sem. 2025'!C163+'C.R Sem. 2025'!C172+'C.R Sem. 2025'!C181+'C.R Sem. 2025'!C190) -> 156 | D26: =SUM('C.R Sem. 2025'!D163+'C.R Sem. 2025'!D172+'C.R Sem. 2025'!D181+'C.R Sem. 2025'!D190) -> 0 | E26: =SUM('C.R Sem. 2025'!E163+'C.R Sem. 2025'!E172+'C.R Sem. 2025'!E181+'C.R Sem. 2025'!E190) -> 0 | F26: =SUM('C.R Sem. 2025'!F163+'C.R Sem. 2025'!F172+'C.R Sem. 2025'!F181+'C.R Sem. 2025'!F190) -> 0 | G26: =SUM('C.R Sem. 2025'!G163+'C.R Sem. 2025'!G172+'C.R Sem. 2025'!G181+'C.R Sem. 2025'!G190) -> 0 | H26: =SUM('C.R Sem. 2025'!H163+'C.R Sem. 2025'!H172+'C.R Sem. 2025'!H181+'C.R Sem. 2025'!H190) -> 0 | I26: =SUM('C.R Sem. 2025'!I163+'C.R Sem. 2025'!I172+'C.R Sem. 2025'!I181+'C.R Sem. 2025'!I190) -> 291 | J26: =SUM('C.R Sem. 2025'!J163+'C.R Sem. 2025'!J172+'C.R Sem. 2025'!J181+'C.R Sem. 2025'!J190) -> 341
A27: Juin | B27: Oui | C27: =SUM('C.R Sem. 2025'!C192+'C.R Sem. 2025'!C202+'C.R Sem. 2025'!C212+'C.R Sem. 2025'!C222) -> 27 | D27: =SUM('C.R Sem. 2025'!D192+'C.R Sem. 2025'!D202+'C.R Sem. 2025'!D212+'C.R Sem. 2025'!D222) -> 0 | E27: =SUM('C.R Sem. 2025'!E192+'C.R Sem. 2025'!E202+'C.R Sem. 2025'!E212+'C.R Sem. 2025'!E222) -> 0 | F27: =SUM('C.R Sem. 2025'!F192+'C.R Sem. 2025'!F202+'C.R Sem. 2025'!F212+'C.R Sem. 2025'!F222) -> 0 | G27: =SUM('C.R Sem. 2025'!G192+'C.R Sem. 2025'!G202+'C.R Sem. 2025'!G212+'C.R Sem. 2025'!G222) -> 0 | H27: =SUM('C.R Sem. 2025'!H192+'C.R Sem. 2025'!H202+'C.R Sem. 2025'!H212+'C.R Sem. 2025'!H222) -> 0 | I27: =SUM('C.R Sem. 2025'!I192+'C.R Sem. 2025'!I202+'C.R Sem. 2025'!I212+'C.R Sem. 2025'!I222) -> 4 | J27: =SUM('C.R Sem. 2025'!J192+'C.R Sem. 2025'!J202+'C.R Sem. 2025'!J212+'C.R Sem. 2025'!J222) -> 9 | K27: =SUM(C27:J27) -> 40 | L27: Nouveaux contrats
B28: À réfléchir | C28: =SUM('C.R Sem. 2025'!C195+'C.R Sem. 2025'!C205+'C.R Sem. 2025'!C215+'C.R Sem. 2025'!C225) -> 48 | D28: =SUM('C.R Sem. 2025'!D195+'C.R Sem. 2025'!D205+'C.R Sem. 2025'!D215+'C.R Sem. 2025'!D225) -> 0 | E28: =SUM('C.R Sem. 2025'!E195+'C.R Sem. 2025'!E205+'C.R Sem. 2025'!E215+'C.R Sem. 2025'!E225) -> 0 | F28: =SUM('C.R Sem. 2025'!F195+'C.R Sem. 2025'!F205+'C.R Sem. 2025'!F215+'C.R Sem. 2025'!F225) -> 0 | G28: =SUM('C.R Sem. 2025'!G195+'C.R Sem. 2025'!G205+'C.R Sem. 2025'!G215+'C.R Sem. 2025'!G225) -> 0 | H28: =SUM('C.R Sem. 2025'!H195+'C.R Sem. 2025'!H205+'C.R Sem. 2025'!H215+'C.R Sem. 2025'!H225) -> 0 | I28: =SUM('C.R Sem. 2025'!I195+'C.R Sem. 2025'!I205+'C.R Sem. 2025'!I215+'C.R Sem. 2025'!I225) -> 39 | J28: =SUM('C.R Sem. 2025'!J195+'C.R Sem. 2025'!J205+'C.R Sem. 2025'!J215+'C.R Sem. 2025'!J225) -> 26
B29: Total d'appel | C29: =SUM('C.R Sem. 2025'!C197+'C.R Sem. 2025'!C207+'C.R Sem. 2025'!C217+'C.R Sem. 2025'!C227) -> 252 | D29: =SUM('C.R Sem. 2025'!D197+'C.R Sem. 2025'!D207+'C.R Sem. 2025'!D217+'C.R Sem. 2025'!D227) -> 0 | E29: =SUM('C.R Sem. 2025'!E197+'C.R Sem. 2025'!E207+'C.R Sem. 2025'!E217+'C.R Sem. 2025'!E227) -> 0 | F29: =SUM('C.R Sem. 2025'!F197+'C.R Sem. 2025'!F207+'C.R Sem. 2025'!F217+'C.R Sem. 2025'!F227) -> 0 | G29: =SUM('C.R Sem. 2025'!G197+'C.R Sem. 2025'!G207+'C.R Sem. 2025'!G217+'C.R Sem. 2025'!G227) -> 0 | H29: =SUM('C.R Sem. 2025'!H197+'C.R Sem. 2025'!H207+'C.R Sem. 2025'!H217+'C.R Sem. 2025'!H227) -> 0 | I29: =SUM('C.R Sem. 2025'!I197+'C.R Sem. 2025'!I207+'C.R Sem. 2025'!I217+'C.R Sem. 2025'!I227) -> 347 | J29: =SUM('C.R Sem. 2025'!J197+'C.R Sem. 2025'!J207+'C.R Sem. 2025'!J217+'C.R Sem. 2025'!J227) -> 284
B30: Total trier | C30: =SUM('C.R Sem. 2025'!C198+'C.R Sem. 2025'!C208+'C.R Sem. 2025'!C218+'C.R Sem. 2025'!C228) -> 251 | D30: =SUM('C.R Sem. 2025'!D198+'C.R Sem. 2025'!D208+'C.R Sem. 2025'!D218+'C.R Sem. 2025'!D228) -> 0 | E30: =SUM('C.R Sem. 2025'!E198+'C.R Sem. 2025'!E208+'C.R Sem. 2025'!E218+'C.R Sem. 2025'!E228) -> 0 | F30: =SUM('C.R Sem. 2025'!F198+'C.R Sem. 2025'!F208+'C.R Sem. 2025'!F218+'C.R Sem. 2025'!F228) -> 0 | G30: =SUM('C.R Sem. 2025'!G198+'C.R Sem. 2025'!G208+'C.R Sem. 2025'!G218+'C.R Sem. 2025'!G228) -> 0 | H30: =SUM('C.R Sem. 2025'!H198+'C.R Sem. 2025'!H208+'C.R Sem. 2025'!H218+'C.R Sem. 2025'!H228) -> 0 | I30: =SUM('C.R Sem. 2025'!I198+'C.R Sem. 2025'!I208+'C.R Sem. 2025'!I218+'C.R Sem. 2025'!I228) -> 352 | J30: =SUM('C.R Sem. 2025'!J198+'C.R Sem. 2025'!J208+'C.R Sem. 2025'!J218+'C.R Sem. 2025'!J228) -> 224
B31: Nbre d'ent. ouvert | C31: =SUM('C.R Sem. 2025'!C200+'C.R Sem. 2025'!C210+'C.R Sem. 2025'!C220+'C.R Sem. 2025'!C230) -> 247 | D31: =SUM('C.R Sem. 2025'!D200+'C.R Sem. 2025'!D210+'C.R Sem. 2025'!D220+'C.R Sem. 2025'!D230) -> 0 | E31: =SUM('C.R Sem. 2025'!E200+'C.R Sem. 2025'!E210+'C.R Sem. 2025'!E220+'C.R Sem. 2025'!E230) -> 0 | F31: =SUM('C.R Sem. 2025'!F200+'C.R Sem. 2025'!F210+'C.R Sem. 2025'!F220+'C.R Sem. 2025'!F230) -> 0 | G31: =SUM('C.R Sem. 2025'!G200+'C.R Sem. 2025'!G210+'C.R Sem. 2025'!G220+'C.R Sem. 2025'!G230) -> 0 | H31: =SUM('C.R Sem. 2025'!H200+'C.R Sem. 2025'!H210+'C.R Sem. 2025'!H220+'C.R Sem. 2025'!H230) -> 0 | I31: =SUM('C.R Sem. 2025'!I200+'C.R Sem. 2025'!I210+'C.R Sem. 2025'!I220+'C.R Sem. 2025'!I230) -> 342 | J31: =SUM('C.R Sem. 2025'!J200+'C.R Sem. 2025'!J210+'C.R Sem. 2025'!J220+'C.R Sem. 2025'!J230) -> 204
A32: Juillet | B32: Oui | C32: =SUM('C.R Sem. 2025'!C232+'C.R Sem. 2025'!C242+'C.R Sem. 2025'!C252+'C.R Sem. 2025'!C262+'C.R Sem. 2025'!C272) -> 32 | D32: =SUM('C.R Sem. 2025'!D232+'C.R Sem. 2025'!D242+'C.R Sem. 2025'!D252+'C.R Sem. 2025'!D262+'C.R Sem. 2025'!D272) -> 0 | E32: =SUM('C.R Sem. 2025'!E232+'C.R Sem. 2025'!E242+'C.R Sem. 2025'!E252+'C.R Sem. 2025'!E262+'C.R Sem. 2025'!E272) -> 0 | F32: =SUM('C.R Sem. 2025'!F232+'C.R Sem. 2025'!F242+'C.R Sem. 2025'!F252+'C.R Sem. 2025'!F262+'C.R Sem. 2025'!F272) -> 0 | G32: =SUM('C.R Sem. 2025'!G232+'C.R Sem. 2025'!G242+'C.R Sem. 2025'!G252+'C.R Sem. 2025'!G262+'C.R Sem. 2025'!G272) -> 5 | H32: =SUM('C.R Sem. 2025'!H232+'C.R Sem. 2025'!H242+'C.R Sem. 2025'!H252+'C.R Sem. 2025'!H262+'C.R Sem. 2025'!H272) -> 17 | I32: =SUM('C.R Sem. 2025'!I232+'C.R Sem. 2025'!I242+'C.R Sem. 2025'!I252+'C.R Sem. 2025'!I262+'C.R Sem. 2025'!I272) -> 3 | J32: =SUM('C.R Sem. 2025'!J232+'C.R Sem. 2025'!J242+'C.R Sem. 2025'!J252+'C.R Sem. 2025'!J262+'C.R Sem. 2025'!J272) -> 4 | K32: =SUM(C32:J32) -> 61 | L32: Nouveaux contrats
B33: À réfléchir | C33: =SUM('C.R Sem. 2025'!C235,'C.R Sem. 2025'!C245,'C.R Sem. 2025'!C255,'C.R Sem. 2025'!C265,'C.R Sem. 2025'!C275) -> 32 | D33: =SUM('C.R Sem. 2025'!D235,'C.R Sem. 2025'!D245,'C.R Sem. 2025'!D255,'C.R Sem. 2025'!D265,'C.R Sem. 2025'!D275) -> 0 | E33: =SUM('C.R Sem. 2025'!E235,'C.R Sem. 2025'!E245,'C.R Sem. 2025'!E255,'C.R Sem. 2025'!E265,'C.R Sem. 2025'!E275) -> 0 | F33: =SUM('C.R Sem. 2025'!F235,'C.R Sem. 2025'!F245,'C.R Sem. 2025'!F255,'C.R Sem. 2025'!F265,'C.R Sem. 2025'!F275) -> 0 | G33: =SUM('C.R Sem. 2025'!G235,'C.R Sem. 2025'!G245,'C.R Sem. 2025'!G255,'C.R Sem. 2025'!G265,'C.R Sem. 2025'!G275) -> 3 | H33: =SUM('C.R Sem. 2025'!H235,'C.R Sem. 2025'!H245,'C.R Sem. 2025'!H255,'C.R Sem. 2025'!H265,'C.R Sem. 2025'!H275) -> 21 | I33: =SUM('C.R Sem. 2025'!I235,'C.R Sem. 2025'!I245,'C.R Sem. 2025'!I255,'C.R Sem. 2025'!I265,'C.R Sem. 2025'!I275) -> 20 | J33: =SUM('C.R Sem. 2025'!J235,'C.R Sem. 2025'!J245,'C.R Sem. 2025'!J255,'C.R Sem. 2025'!J265,'C.R Sem. 2025'!J275) -> 9
B34: Total d'appel | C34: =SUM('C.R Sem. 2025'!C237,'C.R Sem. 2025'!C247,'C.R Sem. 2025'!C257,'C.R Sem. 2025'!C267,'C.R Sem. 2025'!C277) -> 306 | D34: =SUM('C.R Sem. 2025'!D237,'C.R Sem. 2025'!D247,'C.R Sem. 2025'!D257,'C.R Sem. 2025'!D267,'C.R Sem. 2025'!D277) -> 0 | E34: =SUM('C.R Sem. 2025'!E237,'C.R Sem. 2025'!E247,'C.R Sem. 2025'!E257,'C.R Sem. 2025'!E267,'C.R Sem. 2025'!E277) -> 0 | F34: =SUM('C.R Sem. 2025'!F237,'C.R Sem. 2025'!F247,'C.R Sem. 2025'!F257,'C.R Sem. 2025'!F267,'C.R Sem. 2025'!F277) -> 0 | G34: =SUM('C.R Sem. 2025'!G237,'C.R Sem. 2025'!G247,'C.R Sem. 2025'!G257,'C.R Sem. 2025'!G267,'C.R Sem. 2025'!G277) -> 36 | H34: =SUM('C.R Sem. 2025'!H237,'C.R Sem. 2025'!H247,'C.R Sem. 2025'!H257,'C.R Sem. 2025'!H267,'C.R Sem. 2025'!H277) -> 194 | I34: =SUM('C.R Sem. 2025'!I237,'C.R Sem. 2025'!I247,'C.R Sem. 2025'!I257,'C.R Sem. 2025'!I267,'C.R Sem. 2025'!I277) -> 118 | J34: =SUM('C.R Sem. 2025'!J237,'C.R Sem. 2025'!J247,'C.R Sem. 2025'!J257,'C.R Sem. 2025'!J267,'C.R Sem. 2025'!J277) -> 113
B35: Total trier | C35: =SUM('C.R Sem. 2025'!C238,'C.R Sem. 2025'!C248,'C.R Sem. 2025'!C258,'C.R Sem. 2025'!C268,'C.R Sem. 2025'!C278) -> 298 | D35: =SUM('C.R Sem. 2025'!D238,'C.R Sem. 2025'!D248,'C.R Sem. 2025'!D258,'C.R Sem. 2025'!D268,'C.R Sem. 2025'!D278) -> 0 | E35: =SUM('C.R Sem. 2025'!E238,'C.R Sem. 2025'!E248,'C.R Sem. 2025'!E258,'C.R Sem. 2025'!E268,'C.R Sem. 2025'!E278) -> 0 | F35: =SUM('C.R Sem. 2025'!F238,'C.R Sem. 2025'!F248,'C.R Sem. 2025'!F258,'C.R Sem. 2025'!F268,'C.R Sem. 2025'!F278) -> 0 | G35: =SUM('C.R Sem. 2025'!G238,'C.R Sem. 2025'!G248,'C.R Sem. 2025'!G258,'C.R Sem. 2025'!G268,'C.R Sem. 2025'!G278) -> 0 | H35: =SUM('C.R Sem. 2025'!H238,'C.R Sem. 2025'!H248,'C.R Sem. 2025'!H258,'C.R Sem. 2025'!H268,'C.R Sem. 2025'!H278) -> 183 | I35: =SUM('C.R Sem. 2025'!I238,'C.R Sem. 2025'!I248,'C.R Sem. 2025'!I258,'C.R Sem. 2025'!I268,'C.R Sem. 2025'!I278) -> 118 | J35: =SUM('C.R Sem. 2025'!J238,'C.R Sem. 2025'!J248,'C.R Sem. 2025'!J258,'C.R Sem. 2025'!J268,'C.R Sem. 2025'!J278) -> 130
B36: Nbre d'ent. ouvert | C36: =SUM('C.R Sem. 2025'!C240,'C.R Sem. 2025'!C250,'C.R Sem. 2025'!C260,'C.R Sem. 2025'!C270,'C.R Sem. 2025'!C280) -> 296 | D36: =SUM('C.R Sem. 2025'!D240,'C.R Sem. 2025'!D250,'C.R Sem. 2025'!D260,'C.R Sem. 2025'!D270,'C.R Sem. 2025'!D280) -> 0 | E36: =SUM('C.R Sem. 2025'!E240,'C.R Sem. 2025'!E250,'C.R Sem. 2025'!E260,'C.R Sem. 2025'!E270,'C.R Sem. 2025'!E280) -> 0 | F36: =SUM('C.R Sem. 2025'!F240,'C.R Sem. 2025'!F250,'C.R Sem. 2025'!F260,'C.R Sem. 2025'!F270,'C.R Sem. 2025'!F280) -> 0 | G36: =SUM('C.R Sem. 2025'!G240,'C.R Sem. 2025'!G250,'C.R Sem. 2025'!G260,'C.R Sem. 2025'!G270,'C.R Sem. 2025'!G280) -> 0 | H36: =SUM('C.R Sem. 2025'!H240,'C.R Sem. 2025'!H250,'C.R Sem. 2025'!H260,'C.R Sem. 2025'!H270,'C.R Sem. 2025'!H280) -> 186 | I36: =SUM('C.R Sem. 2025'!I240,'C.R Sem. 2025'!I250,'C.R Sem. 2025'!I260,'C.R Sem. 2025'!I270,'C.R Sem. 2025'!I280) -> 118 | J36: =SUM('C.R Sem. 2025'!J240,'C.R Sem. 2025'!J250,'C.R Sem. 2025'!J260,'C.R Sem. 2025'!J270,'C.R Sem. 2025'!J280) -> 127
A37: Août | B37: Oui | C37: =SUM('C.R Sem. 2025'!C282,'C.R Sem. 2025'!C292,'C.R Sem. 2025'!C302,'C.R Sem. 2025'!C312) -> 33 | D37: =SUM('C.R Sem. 2025'!D282,'C.R Sem. 2025'!D292,'C.R Sem. 2025'!D302,'C.R Sem. 2025'!D312) -> 10 | E37: =SUM('C.R Sem. 2025'!E282,'C.R Sem. 2025'!E292,'C.R Sem. 2025'!E302,'C.R Sem. 2025'!E312) -> 3 | F37: =SUM('C.R Sem. 2025'!F282,'C.R Sem. 2025'!F292,'C.R Sem. 2025'!F302,'C.R Sem. 2025'!F312) -> 0 | G37: =SUM('C.R Sem. 2025'!G282,'C.R Sem. 2025'!G292,'C.R Sem. 2025'!G302,'C.R Sem. 2025'!G312) -> 16 | H37: =SUM('C.R Sem. 2025'!H282,'C.R Sem. 2025'!H292,'C.R Sem. 2025'!H302,'C.R Sem. 2025'!H312) -> 21 | I37: =SUM('C.R Sem. 2025'!I282,'C.R Sem. 2025'!I292,'C.R Sem. 2025'!I302,'C.R Sem. 2025'!I312) -> 0 | J37: =SUM('C.R Sem. 2025'!J282,'C.R Sem. 2025'!J292,'C.R Sem. 2025'!J302,'C.R Sem. 2025'!J312) -> 0 | K37: =SUM(C37:J37) -> 83
B38: À réfléchir | C38: =SUM('C.R Sem. 2025'!C285,'C.R Sem. 2025'!C295,'C.R Sem. 2025'!C305,'C.R Sem. 2025'!C315) -> 18 | D38: =SUM('C.R Sem. 2025'!D285,'C.R Sem. 2025'!D295,'C.R Sem. 2025'!D305,'C.R Sem. 2025'!D315) -> 28 | E38: =SUM('C.R Sem. 2025'!E285,'C.R Sem. 2025'!E295,'C.R Sem. 2025'!E305,'C.R Sem. 2025'!E315) -> 10 | F38: =SUM('C.R Sem. 2025'!F285,'C.R Sem. 2025'!F295,'C.R Sem. 2025'!F305,'C.R Sem. 2025'!F315) -> 0 | G38: =SUM('C.R Sem. 2025'!G285,'C.R Sem. 2025'!G295,'C.R Sem. 2025'!G305,'C.R Sem. 2025'!G315) -> 31 | H38: =SUM('C.R Sem. 2025'!H285,'C.R Sem. 2025'!H295,'C.R Sem. 2025'!H305,'C.R Sem. 2025'!H315) -> 66 | I38: =SUM('C.R Sem. 2025'!I285,'C.R Sem. 2025'!I295,'C.R Sem. 2025'!I305,'C.R Sem. 2025'!I315) -> 0 | J38: =SUM('C.R Sem. 2025'!J285,'C.R Sem. 2025'!J295,'C.R Sem. 2025'!J305,'C.R Sem. 2025'!J315) -> 0
B39: Total d'appel | C39: =SUM('C.R Sem. 2025'!C287,'C.R Sem. 2025'!C297,'C.R Sem. 2025'!C307,'C.R Sem. 2025'!C317) -> 170 | D39: =SUM('C.R Sem. 2025'!D287,'C.R Sem. 2025'!D297,'C.R Sem. 2025'!D307,'C.R Sem. 2025'!D317) -> 135 | E39: =SUM('C.R Sem. 2025'!E287,'C.R Sem. 2025'!E297,'C.R Sem. 2025'!E307,'C.R Sem. 2025'!E317) -> 45 | F39: =SUM('C.R Sem. 2025'!F287,'C.R Sem. 2025'!F297,'C.R Sem. 2025'!F307,'C.R Sem. 2025'!F317) -> 0 | G39: =SUM('C.R Sem. 2025'!G287,'C.R Sem. 2025'!G297,'C.R Sem. 2025'!G307,'C.R Sem. 2025'!G317) -> 317 | H39: =SUM('C.R Sem. 2025'!H287,'C.R Sem. 2025'!H297,'C.R Sem. 2025'!H307,'C.R Sem. 2025'!H317) -> 323 | I39: =SUM('C.R Sem. 2025'!I287,'C.R Sem. 2025'!I297,'C.R Sem. 2025'!I307,'C.R Sem. 2025'!I317) -> 0 | J39: =SUM('C.R Sem. 2025'!J287,'C.R Sem. 2025'!J297,'C.R Sem. 2025'!J307,'C.R Sem. 2025'!J317) -> 0
B40: Total trier | C40: =SUM('C.R Sem. 2025'!C288,'C.R Sem. 2025'!C298,'C.R Sem. 2025'!C308,'C.R Sem. 2025'!C318) -> 149 | D40: =SUM('C.R Sem. 2025'!D288,'C.R Sem. 2025'!D298,'C.R Sem. 2025'!D308,'C.R Sem. 2025'!D318) -> 80 | E40: =SUM('C.R Sem. 2025'!E288,'C.R Sem. 2025'!E298,'C.R Sem. 2025'!E308,'C.R Sem. 2025'!E318) -> 43 | F40: =SUM('C.R Sem. 2025'!F288,'C.R Sem. 2025'!F298,'C.R Sem. 2025'!F308,'C.R Sem. 2025'!F318) -> 0 | G40: =SUM('C.R Sem. 2025'!G288,'C.R Sem. 2025'!G298,'C.R Sem. 2025'!G308,'C.R Sem. 2025'!G318) -> 183 | H40: =SUM('C.R Sem. 2025'!H288,'C.R Sem. 2025'!H298,'C.R Sem. 2025'!H308,'C.R Sem. 2025'!H318) -> 310 | I40: =SUM('C.R Sem. 2025'!I288,'C.R Sem. 2025'!I298,'C.R Sem. 2025'!I308,'C.R Sem. 2025'!I318) -> 0 | J40: =SUM('C.R Sem. 2025'!J288,'C.R Sem. 2025'!J298,'C.R Sem. 2025'!J308,'C.R Sem. 2025'!J318) -> 0
...

Sheet Suivi Terrain
A1: Commercial | B1: Date | C1: Heure de Rendez-vous | D1: Heure de départ du bureau | E1: Retour au bureau | F1: Heure de retour au bureau | G1: Heure de fin de journée/matinée | H1: Durée | I1: Raison | J1: Nombre de visite | K1: Entreprise visiter | L1: Compte Rendu
A2: Amanda | B2: 45810 | C2: 0.70833333 | D2: 0.69444444 | E2: Non | F2: - | G2: 0.70833333 | H2: =G2-D2 -> 0.013888889 | I2: Signature contrat + fin de contrat de Madame Anne-Laure Maillot | J2: 1 | K2: CHROME | L2: Documents signés.
A3: Brice | B3: 45810 | C3: - | D3: 0.625 | E3: Non | F3: - | G3: 0.66666667 | H3: =G3-D3 -> 0.041666667 | I3: Signature de document | J3: 1 | K3: MINISO DUPARC | L3: Reçu les coordonnées de la RH qui s'occupe de tout ça.
A4: Brice | B4: 45819 | C4: - | D4: 0.52083333 | E4: Non | F4: - | G4: 0.64583333 | H4: =G4-D4 -> 0.125 | I4: Prospection | J4: 5 | K4: ISHOP Ste Suzanne BIJOUTERIE CARA Ste Suzanne OCEANOR Ste Suzanne SAS EJD (Turbo reunion) Ste Suzanne SARL NLPG LOCATION Ste Suzanne | L4: - Visite avec Turbo concluant. (en attente retour) - Océanor reçu le mail de la rh vers qui s'adresser.
A5: Brice | B5: 45825 | C5: - | D5: 0.45833333 | E5: Oui | F5: 0.52083333 | G5: 0.5 | H5: =G5-D5 -> 0.041666667 | I5: Signature des documents commerciaux | J5: 1 | K5: TURBO Ste Suzanne | L5: Concluant - recherche 1 vendeur pour St Pierre
